Workbook

Sheet ERA5和其他数据源组合调研(补充算法组的数据源信息)
A1: 数据类型分类(标红的代表数据组已经下载的数据) | B1: 编号(红色编号对应算法组需要使用的数据) | C1: 算法组使用说明 | D1: 数据名称 | E1: 对应风场预测本体类别(对应禧蕾那边本体设计) | F1: 对应风场预测本体节点(对应禧蕾那边本体节点) | G1: 分辨率（时/空） | H1: 优先级 | I1: 数据格式 | J1: 是否(开源/下载/有无数据) | K1: 下载链接 | L1: 样本数据下载 | M1: 核心字段 | N1: 缺失值规则 | O1: 元数据表征 | P1: 特征维度 | Q1: 数据获取难度 | R1: 数据源优先级与获取难度评判标准 | S1: 成本/费用 | T1: 数据更新延迟 | U1: 历史数据年限 | V1: 地理覆盖范围 | W1: 用途 | X1: 备注 | Y1: 本地数据样本下载位置
A2: =INDEX(数据源对应的文献以及数据使用方法和条目需求!A:B,MATCH(B2,数据源对应的文献以及数据使用方法和条目需求!B:B,0),1) -> ERA5相关性数据 | B2: AIA-1064 | C2: 使用✅ | D2: 气象站实测ISD(风速/风向/温度/气压/湿度) | E2: 气象与环境； 相邻/上游测风站数据 | F2: 气象与环境(数据源类型-实测值)； 相邻/上游测风站数据(历史风速) | G2: 时：小时级（1h/3h，单条记录对应单次观测）；空：站点级（全球 90°S~90°N，180°W~180°E） | H2: 🔴 必需 | I2: ASCII 字符格式（含 ISD-Lite 精简 CSV 版） | J2: 开源✅ 下载✅(部分需注册) 有数据✅ | K2: 中国气象数据网：https://data.cma.cn/； ISD 全球站点：https://www.ncei.noaa.gov/pub/data/noaa | L2: 陈林老师已经完成1901-2025的数据下载（天翼云） | M2: 1. 站点元数据字段（含长度 + 规则）： USAF (6 位)：美国空军主站标识符，2013 年起首位可为字母； WBAN (5 位)：NCEI WBAN 标识符，数字 0-9； CTRY (2 位)：FIPS 国家代码（如 CN = 中国、US = 美国）； ST (2 位)：美国州代码（仅美国站点）； ICAO (4 位)：机场代码（如 ZBAA = 北京，缺失为空白 / 9999）； LAT (7 位)：纬度（千分之一度，南纬为负，缩放因子 1000）； LON (8 位)：经度（千分之一度，西经为负，缩放因子 1000）； ELEV (5 位)：海拔（米，+9999 = 缺失）； BEGIN (8 位)：起始日期（YYYYMMDD）； END (8 位)：结束日期（YYYYMMDD，99991231 = 持续更新 2. 气象要素：风速 / 风向 / 阵风、气温 / 露点、云量、海平面气压 / 站点气压、当前天气 / 能见度、分时段降水量、积雪深度、其他观测要素（如高度表设置） | N2: 1. 站点元数据缺失值： LAT=+99999、LON=+999999； ELEV=+9999（相对于平均海平面 MSL）； ICAO = 空白 / 9999； BEGIN=00000000、END=99991231（表示持续更新）； 2. 气象要素缺失值：气温 / 气压类 = 9999.9、风 / 能见度类 = 999.9、降水 = 99.99、雪深 = 999.9； | O2: 1. 数据集核心元数据：数据集 ID (DS3505)、维护机构 (NOAA 国家环境信息中心 (NCEI) + 美国空军第 14 气象中队)、数据来源 (ASOS/AWOS/SYNOP/METAR/SHIP 等地面观测数据)； 2. LAT/LON 缩放因子 1000（解码示例：latitude_deg = int (LAT)/1000.0，如 + 39900→39.900°N；longitude_deg = int (LON)/1000.0，如 - 116400→-116.400°W； 3. 时间 / 空间：时间基准 (UTC)、空间覆盖 (全球 90°S~90°N，180°W~180°E) | P2: 地理特征维度：经纬度（LAT_DEG/LON_DEG，千分之一度转换为十进制度）、海拔（ELEV，相对于平均海平面）、站点标识（USAF/WBAN/CTRY/ST/ICAO）； 气象特征维度：风要素（风速 u/v 分量、风向、最大阵风）、温湿要素（气温、露点温度、相对湿度）、气压要素（海平面气压、站点气压）、降水 / 积雪要素（降水量、雪深）、天气现象要素（雾 / 雨 / 雪 / 冰雹等）； 时空特征维度：小时级时序特征（1h/3h 分辨率）、站点级空间特征（单点实测） | Q2: ⭐⭐ 中等 | R2: 第一点：优先级评判标准（优先级用于评估数据源对风场预测项目的重要程度，分为三个等级） 🔴 必需：没有该数据无法开展风场预测或关键评估 判断依据： 1、是模型运行的核心输入数据 2、缺失该数据会导致预测系统无法正常工作 3、是风场预测的基础数据，无法用其他数据替代 4、直接影响预测结果的可用性 典型数据源示例： 1、气象站实测风速/风向 2、数字高程模型(DEM) 3、风机位置与布局图 4、风机SCADA历史数据 5、经纬度与海拔 🟡 推荐：能显著提升精度/鲁棒性但缺失时模型仍可运行 判断依据： 1、能够明显改善预测精度和模型稳定性 2、有助于提升模型的鲁棒性（抗干扰能力） 3、缺失时模型仍可运行，但性能会下降 4、属于重要的辅助数据，但不是绝对必需 典型数据源示例： 1、气象站温度/气压/湿度 2、高分辨率气象同化数据 3、边界层高度数据 4、湍流动能(TKE) 5、垂直风切变指数 🟢 可选：主要用于增强分析或专项研究，对主流程影响较小 判断依据： 1、主要用于深度分析或特定场景研究 2、对主要预测流程影响较小 3、可以用于模型优化，但不是核心需求 4、属于锦上添花的数据，优先级较低 典型数据源示例： 1、卫星散射计海面风场（仅海上风场适用） 2、卫星云图/水汽图 3、气象雷达反射率/径向速度 4、植被指数(NDVI) 5、建筑物高度与密度数据 6、天气形势分型 第二点：数据获取难度评判标准（数据获取难度用于评估获取该数据源所需付出的成本（时间、人力、资金等），分为四个等级） ⭐ 简单：公开/免费、注册即下或直接下载 判断依据： 1、数据完全公开，无需付费 2、下载流程简单，通常只需注册账号 3、可以直接通过网页或API下载 4、无需特殊申请或审批流程 5、获取成本极低，几乎无门槛 典型数据源示例： 1、ERA5再分析数据 2、DEM地形高程数据 3、地表粗糙度/土地利用数据 4、NDVI植被指数数据 ⭐⭐ 中等：需注册/申请或简单对接接口，有一定流程和配额限制 判断依据： 1、需要注册账号或提交简单申请 2、可能需要对接API接口 3、有一定的下载流程和配额限制 4、需要一定的技术能力（如API调用） 5、获取成本中等，有一定门槛但可接受 典型数据源示例： 1、气象站观测数据（部分需注册） 2、卫星数据（需注册Copernicus等平台） 3、MODIS数据（需注册NASA账号） 4、高分辨率气象预报数据（部分需注册） ⭐⭐⭐ 困难：强依赖业主/机构授权或多系统协同，沟通和审批成本高 判断依据： 1、需要向业主或相关机构申请授权 2、需要多系统协同配合 3、沟通和审批流程复杂，耗时较长 4、可能需要签署协议或合同 5、获取成本较高，需要投入较多时间和精力 典型数据源示例： 1、风机SCADA历史数据（需业主授权） 2、风机位置与布局图（需业主提供） 3、气象雷达数据（需向气象部门申请） 4、测风塔观测数据（需业主提供） ⭐⭐⭐⭐ 极难：需自建观测设备或自跑大规模模式，消耗人力+计算资源+资金 判断依据： 1、需要自己建设观测设备 2、需要自己运行大规模数值模式 3、需要大量的人力、计算资源和资金投入 4、技术门槛高，需要专业团队 5、获取成本极高，通常需要项目级投入 典型数据源示例： 1、激光雷达/声雷达测风剖面（需购买设备） 2、区域WRF/COSMO等模式输出（需自跑模式） 3、风机尾流模型输出（需自建模型和计算） | S2: 免费(部分需注册) | T2: 实时/延迟数小时 | U2: SD: 1900 年至今（具体取决于站点）； 中国气象数据网：近 10-20 年 | V2: 全球（纬度 90°S~90°N，经度 180°W~180°E），9000 + 气象站点 | W2: 1. 提供气象站实测风速 / 风向 / 温 / 压 / 湿等小时级观测数据 2. 用于风场预测模型训练、验证、订正 3. 作为风资源评估与数值模拟结果的实测基准 | X2: 1. 记录结构：变长记录（最大长度 2844 字符），包含： 控制数据段（60 字符，固定）、强制数据段（45 字符，固定）、附加数据段（0-637 字符）、备注数据段（最大 515 字符）、元素质量数据段（最大 1587 字符）； 2. 唯一站点 ID：USAF (6 位)+WBAN (5 位)（示例：723150-03812）； 3. 文件名约定：USAF-WBAN - 年份（示例：723150-03812-2023）； 4. 注意事项： ① 站点数据可能存在观测空缺（BEGIN/END 仅表示有数据时段）； ② 多源数据经纬度 / 海拔可能略有差异（非站点搬迁）； ③ 站点搬迁时分配新标识符，历史数据保留原 ID | Y2: D:\dcsk\knowledge_graph_1014\download_data\geodata\data\舟山\ISD\584770-99999-2024.gz；天翼云上存储全量数据：/home/admin/data_set/mvp_data/noaa_isd_samples
A3: =INDEX(数据源对应的文献以及数据使用方法和条目需求!A:B,MATCH(B3,数据源对应的文献以及数据使用方法和条目需求!B:B,0),1) -> 官方业务全球预报数据 | B3: AIA-1097 | C3: 使用✅ | D3: ECMWF HRES 全球预报数据（免费版 0.25°/ 商业版 < 0.1°） | E3: 气象与环境 | F3: 气象与环境 (高空风速风向 - 高精度预报（10m U/V 风分量 u10/v10）、地表气压（sp）、干球温度（2t，样本数据未包含）、大气稳定度 - blh（边界层高度，样本数据未包含）) | G3: 时：3h（验证确认符合 1-3h 要求）；空：0.25°（免费版≈28km）/<0.1°（商业版≈10km） | H3: 🟡 推荐 | I3: GRIB/NetCDF（样本为 GRIB2 格式，已成功转换为 NetCDF 验证文件） | J3: 开源❌ 下载⚠️(付费许可) 有数据✅ | K3: ECMWF HRES：https://data.ecmwf.int/forecasts/20260312/00z/ifs/0p25/oper/ | L3: ⚠️(付费许可)（免费版可获取 0.25° 分辨率数据，<0.1° 高精度数据需购买商业许可；样本数据已成功下载，路径：D:\dcsk\knowledge_graph_1014\download_data\geodata\data\ 舟山 \ECMWF\） | M3: 1. 时空元数据字段：时间步长 step（小时）、纬度 latitude（度）、经度 longitude（度）； 2. 实测存在变量：u10、v10、sp、lsm、asn、q、tcwv、rsn、sithick、sot、vsw、strd、ssr、str、ttr、vo、gh、fg10、ewss、w、d、nsss、r、t、u、v、ro、tp、sd、sf、msl、sve、svn、mucape、zos、tcc、skt、ptype、tprate、ssrd、tcw； 3. 派生变量：wind_speed_10m（√(u10²+v10²)）、sp_hpa（sp/100）； 4. 业务需求缺失变量：2t、blh | N3: 1. 时空坐标：无缺失，全球网格全覆盖（舟山区域：29.7382~30.733°N，121.9655~123.102°E）； 2. 要素缺失： ✅ 存在且无缺失：u10/v10/sp（5/5 文件完整）； ❌ 完全缺失：2t/blh（0/5 文件包含）； ✅ 派生变量：wind_speed_10m/sp_hpa 无缺失； 3. 网格无效区：统一用 NaN 标识 | O3: 1. 数据集核心元数据： 来源 (ECMWF HRES 0p25-oper)、模式 (IFS)、分辨率 (0.25° 免费版 /<0.1° 商业版)、格式 (GRIB2/NetCDF)、时区 (UTC)、文件命名规则 (YYYYMMDD000000-XXh-oper-fc.grib2)； 2. 验证结论：数据源合规、时间分辨率 3h 符合要求、空间分辨率 0.25°（免费版限制 | P3: 地理特征维度：latitude（纬度）、longitude（经度）、网格分辨率(0.25°)； 气象特征维度： ✅ 核心：近地面风场 (u10/v10/wind_speed_10m)、地表气压 (sp/sp_hpa)； ✅ 其他：lsm/asn/q/tcwv 等 30 + 气象变量； ❌ 缺失：2m 气温 (2t)、边界层高度 (blh)； 时空特征维度：时间维度（预报时效 48/54/60/66/72h）、空间维度（全球网格化 ~28km）、单要素数值维度。 | Q3: ⭐⭐ 中等 | S3: 付费 (商业使用需购买许可证；非商业科研可申请免费版，仅获取 0.25° 分辨率数据) | T3: 延迟数小时（ECMWF HRES 预报数据发布延迟约 3-6 小时，样本数据无异常延迟） | U3: 近 10-15 年（ECMWF 官方存档周期，样本数据为 20260312 预报数据，在覆盖范围内） | V3: 全球（样本数据覆盖舟山区域：纬度 29.7382~30.733°N，经度 121.9655~123.102°E，无空间偏移） | W3: 1. 业务应用：气象同化输入、近地面风场高精度预报、地表气压分析、大气稳定度评估（需补充2t/blh）； 2. 数据处理：派生10m合成风速、地表气压hPa单位转换，满足AIA-1097业务规范要求； 3. 场景适配：舟山区域气象要素提取、环境气象分析、天气系统识别，支撑相关业务化输出。 | X3: 1. 数据现状：u10/v10/sp 5/5文件完整有效，2t/blh 完全缺失（需在ECMWF下载界面补充勾选对应参数）； 2. 分辨率说明：免费版实际0.25°（≈28km），<0.1°高精度需购买ECMWF商业许可； 3. 派生字段：wind_speed_10m、sp_hpa 基于原始字段计算，符合气象行业业务规范； 4. 格式兼容：原始数据为GRIB2，已成功转换为NetCDF格式，可直接用于后续分析。 | Y3: D:\dcsk\knowledge_graph_1014\download_data\geodata\data\舟山\ECMWF
A4: =INDEX(数据源对应的文献以及数据使用方法和条目需求!A:B,MATCH(B4,数据源对应的文献以及数据使用方法和条目需求!B:B,0),1) -> WRF数据 | B4: AIA-1094 | C4: 使用✅ | D4: 区域WRF/COSMO等模式输出 | E4: 气象与环境 | F4: 气象与环境(高空风速风向-高分辨率、大气稳定度-TKE/PBL) | G4: 时：1-3h；空：1-5 km | H4: 🟡 推荐 | I4: NetCDF | J4: 模式开源✅ 结果需自跑⚠️ 有数据⚠️(需自行运行) | K4: WRF：https://www.mmm.ucar.edu/models/wrf | Q4: ⭐⭐ 中等 | S4: 高成本(需计算资源+专业知识) | T4: 自定义(需自行运行) | U4: 自定义(取决于输入数据) | V4: 自定义(取决于配置) | W4: 1. 业务应用：区域高分辨率气象预报、高空风场精细化分析、大气稳定度评估（TKE/PBL）、中小尺度天气系统模拟； 2. 科研支撑：气象物理过程研究、数据同化方案验证、极端天气事件复盘分析、模式参数优化； 3. 场景适配：复杂地形/下垫面气象要素模拟、航空/风电等行业定制化气象服务、环境气象耦合模拟输入。 | X4: 1. 数据获取：模式开源免费（WRF v4.5及以上版本），但需自行配置输入数据（如ECMWF/FNL）、调试参数并运行； 2. 成本说明：高计算资源需求（CPU/GPU+存储），需具备气象模式运行专业知识，结果精度依赖配置合理性； 3. 时空特性：时间分辨率1-3h可自定义，空间分辨率1-5km支持按需调整，覆盖范围/时间跨度取决于输入数据与运行设置； 4. 核心优势：支持并行计算、物理过程参数化方案丰富，适配从 tens of meters 到 thousands of kilometers 多尺度模拟需求。
A5: =INDEX(数据源对应的文献以及数据使用方法和条目需求!A:B,MATCH(B5,数据源对应的文献以及数据使用方法和条目需求!B:B,0),1) -> ERA5相关性数据 | B5: KG-6 | C5: 未使用❌ | D5: 卫星散射计海面风场(ASCAT OASWC12 沿海风场产品) | E5: 气象与环境 | F5: 气象与环境(高空风速风向-海上补充) | G5: 时：卫星过境（实测单次过境时间：2026-03-12 13:03:00）； 空：12.5-25 km | H5: 🟢 可选 | I5: NetCDF | J5: 开源✅ 下载✅(需注册) 有数据✅(海上区域) | K5: ASCAT：https://data.eumetsat.int/extended?query=OASWC12；Sentinel-1：https://scihub.copernicus.eu/ | L5: 需要注册账号下载(账号：wangdelei密码：Wdl2072706022) | M5: 1. 定位字段：lat（纬度，°）、lon（经度，°）、time（观测时间，UTC）； 2. 风场要素：wind_speed（风速，m s⁻¹，实测存在且字段有效）、wind_dir（风向，°，实测存在且字段有效）； 3. 质量标识：数据质量标记、有效观测标记 | N5: 1. 风要素缺失：wind_speed = 999.9、wind_dir = 999.9； 2. 空间字段缺失：lat = 999.99、lon = 999.99； 3. 无效区域标记：近海/陆地附近为缺失/掩膜值； 4. 无观测区域统一使用缺测值填充 | O5: 1. 数据集核心： 1. 数据集核心： OASWC12 海面风场产品，EUMETSAT 生产，MetOp‑B 卫星观测； 2. 实测元数据： 数据延迟 20.9 小时、空间覆盖纬度 - 89.36~89.27°N / 经度 0.01~360.00°E、仅海上有效（陆地数据为 False）； 3. 验证结论：仅数据格式标注（NetCDF/HDF5）与实测不符（实际仅 NetCDF 4. 字段元数据： - lat/lon：浮点型，单位 ° - wind_speed：浮点型，单位 m s⁻¹ - wind_dir：浮点型，单位 ° - time：UTC 卫星过境时间 5. 时空基准：时间UTC，空间全球海上网格 | P5: 地理特征维度：地理特征维度：经纬度（lat/lon，实测范围 - 89.36~89.27°N，0.01~360.00°E）、全球海上覆盖（陆地数据标记为 False）、12.5km 网格分辨率； 气象特征维度：海面风速、海面风向、风场质量标记； 时空特征维度：卫星过境单次时间、12.5 km 网格空间分辨率 | Q5: ⭐⭐ 中等 | S5: 免费(需注册) | T5: 延迟数小时 - 数天（实测单文件延迟 20.9 小时） | U5: ASCAT: 2007年至今； Sentinel-1: 2014年至今 | V5: 全球 (仅海上区域)，实测覆盖纬度 - 89.36~89.27°N，经度 0.01~360.00°E，陆地数据标记为 False | W5: 1. 提供卫星遥感海面风速/风向数据 2. 用于海上/沿海风场预测模型验证、订正 3. 作为海上背景风场参考与补充数据源 | X5: 1. 数据格式：实测为 NetCDF（NC）格式，非 HDF5 格式； 2. 结构：lat/lon/time 三维结构； 3. 唯一标识：OASWC12_20260312_130300_69953_M01.nc； 4. 注意事项：仅海上有效（陆地数据标记为 False），无陆地数据；使用前需过滤缺失值； 5. 验证结论：除格式标注外，其余元数据（分辨率 / 覆盖 / 字段 / 成本）均与实测一致 | Y5: D:\dcsk\knowledge_graph_1014\download_data\geodata\data\舟山\KG-6\OASWC12_20260312_130300_69953_M01.nc
A6: =INDEX(数据源对应的文献以及数据使用方法和条目需求!A:B,MATCH(B6,数据源对应的文献以及数据使用方法和条目需求!B:B,0),1) -> ERA5相关性数据 | B6: AIA-1081 | C6: 使用✅ | D6: 卫星云图 / 水汽图（Himawari-9 L2CLP010 云特性产品 / JAXA 生产） | E6: 气象与环境 | F6: 气象与环境(全局水平辐照度-间接、近地面微气象-云量/辐射影响) | G6: 时：10min（实测）； 空：2.22km（实测） | H6: 🟢 可选 | I6: NetCDF（实测仅为 NetCDF 格式，三维网格结构 lat/lon/time） | J6: 开源✅ 下载✅(部分需注册) 有数据✅ | K6: Himawari-8：https://www.eorc.jaxa.jp/ptree/； FY-4A：http://satellite.nsmc.org.cn/ | L6: ftp协议连接：21、主机名 (H)：ftp.ptree.jaxa.jp、用户名 (U)：tejerajorge488_gmail.com密码 (P)：SP+wari8 | M6: 1. 定位字段：latitude（degrees_north）、longitude（degrees_east）、time（UTC，实测观测时间 2026-03-12 08:00）； 2. 云 / 水汽要素：CLP（云量概率，%）、COD（云光学厚度，单位 1）、CTH（云顶高度，m）； 3. 质量标识：数据质量标记； 4. 字段单位补充：COD 标注为「单位 1」（无量纲），latitude/longitude 单位标注为 degrees_north/degrees_east | N6: 1. 云 / 水汽要素缺失：CLP=999.9、COD=999.9、CTH=99999.0（实测缺测值）； 2. 空间字段缺失：latitude=999.99、longitude=999.99； 3. 无效区域标记：舟山区域外为掩膜值；无观测区域填充缺测值； 4. 补充：缺测值字典化表述 {'CLP': 999.9, 'COD': 999.9, 'CTH': 99999.0}，便于数据过滤 | O6: 1. 数据集核心：Himawari L2CLP010 云特性产品（实测为 Himawari-9 卫星），JAXA 生产；FY-4A AGRI 云产品，CMA 生产； 2. 字段元数据： - latitude/longitude：浮点型，单位 degrees_north/degrees_east； - CLP：浮点型，单位 %；COD：浮点型，单位 1（无量纲）；CTH：浮点型，单位 m； 3. 时空基准： - 时间：UTC（实测观测时间 2026-03-12 08:00）； - 空间：亚太网格（实测 90.0~180.0°E, 0.0~60.0°N | P6: 地理特征维度：经纬度（latitude/longitude）、舟山区域（121.38~123.07°E, 29.73~30.85°N）、亚太区域（实测 90.0~180.0°E, 0.0~60.0°N）； 气象特征维度：CLP（云量概率）、COD（云光学厚度）、CTH（云顶高度）、数据质量标记； 时空特征维度：10min 单次观测（实测）、2.22km 网格空间分辨率（实测 | Q6: ⭐⭐⭐⭐ 极难 | S6: 免费(部分需注册) | T6: 近实时 / 延迟约 103.6 小时（实测） | U6: FY-4A: 2016年至今；Himawari-8: 2015年至今 | V6: 区域覆盖 (FY-4A: 中国及周边；Himawari-8/9: 亚太（实测 90.0~180.0°E, 0.0~60.0°N）；舟山区域（121.38~123.07°E, 29.73~30.85°N）) | W6: 1. 提供 CLP/COD/CTH 等卫星遥感数据，用于舟山区域近地面微气象模型验证、全局水平辐照度估算、海上 / 沿海气象背景数据补充 | X6: 1. 数据格式：NetCDF 网格数据（实测），三维结构（latitude/longitude/time 维度）； 2. 唯一标识：NC_H09_20260312_0800_L2CLP010_FLDK.02401_02401.nc、NC_H09_20260312_0810_L2CLP010_FLDK.02401_02401.nc； 3. 文件名约定：卫星代号_H09 - 日期_小时 - 产品类型_分辨率（示例：H09_20260312_0800_L2CLP010_FLDK.02401）； 4. 注意事项： - 已裁剪舟山指定区域（121.38~123.07°E, 29.73~30.85°N）； - 实测缺测值：{'CLP': 999.9, 'COD': 999.9, 'CTH': 99999.0}，使用前需过滤无效值； - 不同卫星产品分辨率 / 覆盖范围略有差异，FTP 访问需确认账号权限有效性； 5. 数据缩放规则：经纬度原始精度 0.02°（无需换算），CLP 为百分比直接使用，CTH 单位为米（无需缩放）； | Y6: D:\dcsk\knowledge_graph_1014\download_data\geodata\data\舟山\KG-7\NC_H09_20260312_0800_L2CLP010_FLDK.02401_02401.nc；阿里云全量数据：/data/hdfs/user/zaixi.tang/himawari/2025
A7: =INDEX(数据源对应的文献以及数据使用方法和条目需求!A:B,MATCH(B7,数据源对应的文献以及数据使用方法和条目需求!B:B,0),1) -> 遥感观测数据 | B7: KG-8 | C7: 未使用❌ | D7: 气象雷达反射率/径向速度 | E7: 气象与环境 | F7: 气象与环境(近地面微气象-强对流相关) | G7: 时：~6min 体扫； 空：~1 km，多高度层 | H7: 🟢 可选 | I7: 雷达 Level-II / BUFR | J7: 开源⚠️(需申请) 下载⚠️ 有数据⚠️(视区域) | K7: 中国气象数据网：https://data.cma.cn/（需专项申请） | L7: 需向气象部门提交专项申请，提供项目立项证明 + 数据使用说明，审批通过后获取 FTP/API 访问权限 | M7: 1. 定位字段：lat（纬度，°）、lon（经度，°）、time（体扫时间，UTC/BTC）、height（高度，m） 2. 雷达要素：DBZ（反射率因子，dBZ）、Vr（径向速度，m/s）、SW（谱宽，m/s） 3. 质量标识：数据质量控制标记（QC_flag）、噪声过滤标记、距离折叠标记 | N7: 1. 雷达要素缺失：DBZ=-32768、Vr=-32768、SW=-32768 2. 定位字段缺失：lat=999.99、lon=999.99、height=9999 3. 无效区域标记：雷达覆盖范围外为掩膜值，地物遮挡区域填充缺测值 | O7: 1. 数据集核心：中国气象局新一代天气雷达（CINRAD）Level-II 产品，CMA 气象探测中心生产 2. 字段元数据： - lat/lon：浮点型，单位 °；height：浮点型，单位 m - DBZ：整型，单位 dBZ；Vr/SW：浮点型，单位 m/s 3. 时空基准：时间 UTC/BTC 双基准，空间雷达站点为中心的极坐标网格（转笛卡尔坐标后 1km 分辨率） | P7: 地理特征维度：经纬度（lat/lon）、雷达覆盖区域（半径 150-230km）、垂直高度层（100m-15km） 气象特征维度：反射率因子（DBZ）、径向速度（Vr）、谱宽（SW）、强对流识别标记 时空特征维度：6min 体扫时间分辨率、1km 水平分辨率、100m-1km 垂直分辨率 | Q7: ⭐⭐ 中等 | S7: 免费（需申请审批，无数据使用费 | T7: 实时 / 延迟数分钟（业务运行雷达延迟≤5 分钟，归档数据延迟≤1 小时） | U7: 近 5-10 年 (视雷达站)（新建雷达站存档 3 年 +，骨干雷达站存档 10 年 +） | V7: 区域覆盖 (视雷达站分布)（单站覆盖半径 150-230km，沿海 / 强对流频发区站点密度高） | W7: 1. 提供气象雷达反射率 / 径向速度数据，用于强对流天气（雷暴 / 冰雹 / 短时强降水）监测预警，作为近地面微气象模型强对流过程订正数据源，辅助风场突变事件分析 | X7: 1. 记录结构：Level-II 格式含主数据段 + 质量控制段 + 标定参数段，BUFR 格式为二进制编码结构； 2. 唯一标识：雷达站号（5 位）+ 体扫时间（YYYYMMDDHHMM）+ 产品类型 + 数据级别； 3. 注意事项：数据需使用气象雷达专用解码工具（如 MATLAB 雷达工具箱、Py-ART）处理，需结合雷达站点标定文件进行精度校正，舟山区域主要覆盖雷达站为舟山雷达站（Z9510）及周边宁波（Z9507）、上海（Z9505）雷达站。
A8: =INDEX(数据源对应的文献以及数据使用方法和条目需求!A:B,MATCH(B8,数据源对应的文献以及数据使用方法和条目需求!B:B,0),1) -> 遥感观测数据 | B8: KG-9 | C8: 未使用❌ | D8: 激光雷达/声雷达测风剖面 | E8: 相邻/上游测风站数据 | F8: 相邻/上游测风站数据(历史风速-高精度风廓线、湍流强度/风切变) | G8: 时：1s-10min； 空：垂直10-300m分层 | H8: 🟡 推荐 | I8: CSV/Binary | J8: 开源❌ 下载❌ 有数据⚠️(需现场采集) | K8: 随设备厂商/业主提供 | L8: 需业主/设备方提供，无公开下载渠道 | M8: 1. 定位字段：站点编号、经度LON、纬度LAT、海拔ELEV、测量时间TIME、测量高度HEIGHT； 2. 风场要素：风速WS、风向WD、垂直风速W、湍流强度TI、风切变Shear、信噪比SNR； 3. 质量标识：QC质量标记、有效数据标记、异常值标记 | N8: 1. 定位缺失值：LON=999.999、LAT=999.999、ELEV=9999、HEIGHT=9999； 2. 风场缺失值：WS=99.99、WD=999、TI=99.99、Shear=99.99； 3. 无效标记：QC=2/3/9为异常或缺测 | O8: 1. 数据集：激光雷达/声雷达现场观测数据； 2. 字段：高度分层10~300m，时间1s~10min，单位：m/s、°、m、%； 3. 时空基准：本地时/UTC，单点站点观测 | P8: 地理特征：单点测站位置(LON/LAT/ELEV)、垂直高度层(10~300m)；气象特征：风速、风向、垂直风速、湍流强度TI、风切变、信噪比；时空特征：高频时间序列(1s~10min)、垂直分层空间特征 | Q8: ⭐⭐⭐ 困难 | S8: 高成本(需购买设备+现场部署) | T8: 实时(设备采集) | U8: 设备部署期间 | V8: 站点级(单点观测) | W8: 1. 用于高精度风廓线反演、风切变/湍流计算、风场模拟验证、风机尾流分析、风资源评估高精度输入 | X8: 1. 记录结构：按时间+垂直高度分层存储，CSV/Binary格式； 2. 唯一标识：站点编号_设备编号_起止时间； 3. 文件名约定：站点ID_设备ID_开始时间-结束时间； 4. 注意事项：数据为现场采集，无公开渠道，需厂商/业主提供；需过滤无效值、异常值、低信噪比数据；仅在设备部署期间有观测。
A9: =INDEX(数据源对应的文献以及数据使用方法和条目需求!A:B,MATCH(B9,数据源对应的文献以及数据使用方法和条目需求!B:B,0),1) -> 地理与地表信息数据 | B9: KG-10 | C9: 未使用❌ | D9: 数字高程模型 (DEM)（ASTER GDEM V003） | E9: 空间与地理地形 | F9: 空间与地理地形(地形复杂度、离地高度(风机)-海拔基准) | G9: 时：静态；空：30 m（对应经纬度分辨率 0.000277777777777778°，实测） | H9: 🔴 必需 | I9: GeoTIFF（实测为 GeoTIFF 格式，单波段栅格结构） | J9: 开源✅ 下载✅ 有数据✅ | K9: USGS：https://earthexplorer.usgs.gov/； 地理空间数据云：https://www.gscloud.cn/sources/index?pid=302； | L9: 需要注册账号下载(账号：wangdelei密码：wdl2072706022) | M9: 1. 地理坐标字段：LAT（纬度，十进制度）、LON（经度，十进制度）； 2. 高程核心字段：DEM_BAND_1（地表高程值，单位：米 (m)）； 3. 质量评估字段：NUM_BAND_1（数据质量等级 / 观测次数） | N9: 1. 无效值标识：NoData（None，按栅格文件头信息识别）； 2. 高程异常值：低于海平面（<0m）为有效海洋 / 洼地高程，非缺失值； 3. 质量字段：NUM_BAND_1=0 表示低质量数据，建议剔除 | O9: 1. 数据集核心：发布机构 (USGS/NASA/METI)、数据版本 (ASTER GDEM V003)、坐标参考系 (EPSG:4326，WGS84)； 2. 字段属性：高程单位 (米 (m))、空间分辨率 (30m=0.000277777777777778°，90m=0.000833333°)、栅格尺寸 (3601×3601 像素)； 3. 质量规则：ASTER GDEM V3 高程误差≤15m（95% 置信度），SRTM 高程误差≤16m（90% 置信度） | P9: 1. 地理特征维度：经纬度、海拔高程、站点级 / 栅格级空间位置； 2. 地形特征维度：坡度（Slope）、坡向（Aspect）、地形起伏度、离地高度（风机选址核心指标）； 3. 空间特征维度：30m 栅格精度、全球陆地区域连续覆盖 | Q9: ⭐ 简单 | S9: 免费 | T9: 静态数据(一次性) | U9: ASTER GDEM V3：2000 年 3 月～2013 年 11 月； SRTM：2000 年 2 月～2000 年 3 月 | V9: 全球陆地区域（ASTER GDEM V3：北纬 83°~ 南纬 83°；SRTM：北纬 60°~ 南纬 56°）； 覆盖舟山区域（舟山范围：121.38~123.07°E, 29.73~30.85°N） | W9: 1. 风场地形复杂度分析 2. 风机离地高度计算 3. 尾流效应模拟 4. 坡度、坡向、地形起伏度提取 | X9: 1. 数据选型：30m 精度优先选择 ASTER GDEM V3，90m 精度选择 SRTM； 2. 瓦片命名：按经纬度编码（如 ASTGTMV003_N29E121/SRTM_29_121）； 3. 适用场景：风场地形复杂度分析；风机离地高度计算；尾流效应模拟；坡度、坡向、地形起伏度提取； 4. 注意事项：极地无冰陆地、纯海洋区域无数据，需按经纬度筛选有效瓦片； 5. 舟山覆盖：是； 6. 数据格式：GTiff，单波段栅格，数据类型 int16 | Y9: D:\dcsk\knowledge_graph_1014\download_data\geodata\data\舟山\DEM 30\ASTGTMV003_N30E122\ASTGTMV003_N30E122_dem.tif
A10: =INDEX(数据源对应的文献以及数据使用方法和条目需求!A:B,MATCH(B10,数据源对应的文献以及数据使用方法和条目需求!B:B,0),1) -> 地理与地表信息数据 | B10: KG-11 | C10: 未使用❌ | D10: 地表粗糙度长度 | E10: 空间与地理地形 | F10: 空间与地理地形(下垫面特征-粗糙度) | G10: 时：年度； 空：10 m | H10: 🔴 必需 | I10: GeoTIFF（GTiff，LZW 压缩） | J10: 开源✅ 下载✅ 有数据✅ | K10: ESA WorldCover：https://livingatlas.arcgis.com/landcoverexplorer/； ESA WorldCover：https://esa-worldcover.org/en； GlobeLand30：https://www.webmap.cn/mapDataAction.do?method=globalLandCover | L10: 需要注册账号下载 | M10: 1. 地理坐标：LAT（十进制度）、LON（十进制度）； 2. 核心字段：Z0（地表粗糙度长度，单位：m）； 3. 关联字段：LULC_TYPE（土地利用类型编码，uint8，0‑11 | N10: 1. 缺失值标识：NoData=0.0（编码 0，占比 72.43%）； 2. 无效值：Z0≤0 或 Z0>0.5； 3. 云像元（编码 10）需剔除 | O10: 1. 数据集核心：发布机构 (Esri/ESA)、数据源 (ESRI 10m Annual LULC)、坐标系 EPSG:32651； 2. 字段属性：Z0 单位 (米)、分辨率 10m、栅格尺寸 61044×89013、类型 uint8； 3. 质量规则：基于 ESRI→IGBP 映射，Z0 参考 WRF‑VEGPARM.TBL | P10: 1. 地理特征：经纬度 119.76959~126.23041°E，23.970698~32.035404°N； 2. 下垫面特征：Z0 范围 0.0001‑0.5m，水域占比 42.93%； 3. 时空特征：年度更新，10m 栅格精度 | Q10: ⭐ 简单 | S10: 免费 | T10: 年度更新 | U10: WorldCover:2020/2021 年； GlobeLand30:2000/2010/2020 年； 实测数据：2024 年 | V10: 全球 (单瓦片覆盖 149,820km²，UTM 51 区)； WGS84: Lon[119.76959,126.23041], Lat[23.970698,32.035404] | W10: 1. Z₀通过 ESRI LULC→IGBP→Z0 映射推导； 2. 剔除 Z0≤0 或 > 0.5、NoData、云像元； 3. 瓦片命名：MGRS 100km 网格； 4. 有效面积 149820km² | X10: 1. 地表粗糙度长度 Z₀ 并非原生下载数据，需通过「下载 LULC 土地利用数据 + 基于 WRF 官方 VEGPARM.TBL 经验赋值表进行栅格重分类」推导得到： - 第一步：下载源 LULC 数据（ESA WorldCover 10m / GlobeLand30 30m，GeoTIFF 格式），获取 LULC_TYPE 编码； - 第二步：将 LULC_TYPE 映射至 WRF 官方 USGS/IGBP 分类体系，参考 WRF 3.9 版 VEGPARM.TBL 中 Z₀ 经验赋值表（权威来源：WRF 模式官方静态参数库 `VEGPARM.TBL`），为每类土地利用赋值 Z₀（单位：m，默认取 Z0MIN）； - 第三步：在 QGIS/Python 中执行栅格重分类，将 LULC 编码替换为对应 Z₀ 值； - 第四步：质量控制：剔除 Z₀ ≤ 0 或 Z₀ > 5 的异常值，将海洋/无数据区域标记为 NoData，最终输出 Z₀ 栅格（GeoTIFF 格式）。 2. 适配风场边界层模拟、下垫面粗糙度校正； 3. 海洋、极地无冰区域无数据，需按经纬度筛选陆地区域（剔除外海/冰雪区）。 | Y10: D:\dcsk\knowledge_graph_1014\download_data\geodata\data\舟山\LULC\51R_20240101-20241231.tif
A11: =INDEX(数据源对应的文献以及数据使用方法和条目需求!A:B,MATCH(B11,数据源对应的文献以及数据使用方法和条目需求!B:B,0),1) -> 地理与地表信息数据 | B11: KG-12 | C11: 未使用❌ | D11: 土地利用/土地覆盖(LULC) | E11: 空间与地理地形 | F11: 空间与地理地形(下垫面特征-粗糙度-LULC→z₀) | G11: 时：年度；空：10m | H11: 🔴 必需 | I11: GeoTIFF（LZW 压缩、COG 瓦片、512×512 块） | J11: 开源✅ 下载✅ 有数据✅ | K11: 同上（WorldCover/GlobeLand30 等） | L11: 需要注册账号下载 | M11: 1. 地理坐标：LAT（十进制度）、LON（十进制度），可从投影反算为 WGS84 十进制度； 2. 分类字段：LULC_TYPE（uint8 离散整数编码，0-11）、LULC_NAME（类型名称）； 3. 辅助字段：CONFIDENCE（分类置信度） | N11: 1. 缺失值标识：NoData=0.0（编码 0，占比 72.43%）； 2. 无效值：LULC_TYPE=0（NoData）、10（云）； 3. 无 99 编码 | O11: 1. 数据集核心：发布机构 (Esri/ESA)、数据源：Sentinel-2、分类体系：ESRI 10m Annual LULC、坐标系 EPSG:32651； 2. 字段属性：类型编码 uint8、分辨率 10m、栅格尺寸 61044×89013； 3. 质量规则：可映射至 IGBP 17 类，支持 Z0 推导 | P11: 1. 地理特征：经纬度、空间位置； 2. 下垫面特征：土地利用类型、地表粗糙度关联，可直接映射 Z0（符合 LULC→Z0 需求）； 3. 时空特征：年度更新、10-30m 栅格精度 | Q11: ⭐ 简单 | S11: 免费 | T11: 年度更新 | U11: WorldCover: 2020/2021年； GlobeLand30: 2000/2010/2020年 | V11: 全球 | W11: 1. 下垫面特征分析、地表粗糙度 Z₀ 推导、风场模拟、城市 / 生态监测 | X11: 1. 用于推导地表粗糙度 Z₀，基于 ESRI→IGBP→Z0 映射； 2. 分类体系：ESRI 11 类，可转 IGBP； 3. 坐标系 EPSG:32651，可转 WGS84； 4. 单瓦片覆盖 149,820 km²（中国东部 UTM 51 区）； 5. 水域占比 42.93%，有效像元占比 27.57%。 | Y11: D:\dcsk\knowledge_graph_1014\download_data\geodata\data\舟山\LULC\51R_20240101-20241231.tif
A12: =INDEX(数据源对应的文献以及数据使用方法和条目需求!A:B,MATCH(B12,数据源对应的文献以及数据使用方法和条目需求!B:B,0),1) -> 地理与地表信息数据 | B12: KG-13 | C12: 未使用❌ | D12: 植被指数(NDVI) | E12: 空间与地理地形 | F12: 空间与地理地形(下垫面特征-粗糙度-季节变化) | G12: 时：16 天 / 月度；空：10m（实测 Sentinel-2 R10m） | H12: 🟢 可选 | I12: 原生数据（JP2）、计算后输出（GeoTIFF） | J12: 开源✅ 下载✅(需注册) 有数据✅ | K12: MODIS：https://ladsweb.modaps.eosdis.nasa.gov/； Sentinel-2：https://dataspace.copernicus.eu/ | L12: Sentinel-2：账号：tejerajorge488@gmail.com 密码：!Wdl2072706022 | M12: 1. 地理坐标：LAT（十进制度）、LON（十进制度）； 2. 核心指数：NDVI（归一化植被指数，-1~1）； 3. 辅助字段：QA（MODIS 质量标识）、SCL（Sentinel-2 场景分类） | N12: 1. 缺失值：-9999（Sentinel-2 JP2），实测 NoData 像素数量 = 0； 2. 无效值：NDVI<-1 或> 1（异常值需剔除）； 3. QA（MODIS）/ SCL（Sentinel-2）字段标识云污染 / 无效观测 | O12: 1. 数据集核心：发布机构 (NASA/ESA)、传感器 (MODIS/Sentinel-2 MSI)，Sentinel-2 原生坐标系 EPSG:32651（实测），可转 WGS84； 2. 字段属性：NDVI 单位 (无)、时间分辨率 (16 天 / 月度)、空间分辨率 10m； 3. 质量规则：QA（MODIS）/ SCL（Sentinel-2）字段标识云污染 / 无效观测 | P12: 1. 地理特征：经纬度（舟山定海：29.7382~30.733°N / 121.9655~123.102°E）、空间位置； 2. 植被特征：植被覆盖度、生长季变化； 3. 时空特征：16 天 / 月度更新、10m 栅格精度（实测） | Q12: ⭐ 简单 | S12: 免费(需注册) | T12: 16 天 / 月度更新 | U12: MODIS: 2000年至今； Sentinel-2: 2015年至今 | V12: 全球 | W12: 1. 提供归一化植被指数（NDVI），反映区域植被覆盖度与季节动态变化，用于风场数值模型中地表粗糙度 Z₀ 的季节修正，区分植被区、裸地、建筑区，提升城市与近地面风场模拟的真实性与精度 | X12: 1. 植被指数（NDVI）并非原生下载数据，需通过 Sentinel-2/MODIS 原始波段计算得到： - Sentinel-2：利用红光（B04）与近红外（B08）10m 波段（EPSG:32651），按公式 NDVI = (B08 - B04)/(B08 + B04) 计算； - MODIS：利用 250m 近红外 / 红光波段计算 NDVI，或直接使用 MOD13Q1 预处理 NDVI 产品。 2. 反映植被季节变化，辅助调整地表粗糙度 Z₀ 的季节动态； 3. Sentinel-2（10m）适配舟山定海（29.7382~30.733°N）小范围精细化分析，MODIS（250m）适配大范围宏观分析 | Y12: D:\dcsk\knowledge_graph_1014\download_data\geodata\data\舟山\NDVI\S2A_MSIL2A_20240409T022531_N0510_R046_T51RVP_20240409T055950.SAFE\GRANULE\L2A_T51RVP_A045946_20240409T023525\IMG_DATA\R10m
A13: =INDEX(数据源对应的文献以及数据使用方法和条目需求!A:B,MATCH(B13,数据源对应的文献以及数据使用方法和条目需求!B:B,0),1) -> 地理与地表信息数据 | B13: KG-14 | C13: 未使用❌ | D13: 建筑物高度、密度数据与建筑轮廓数据 | E13: 空间与地理地形 | F13: 空间与地理地形(下垫面特征-障碍物) | G13: 时：静态；空：10-100 m | H13: 🟢 可选 | I13: GeoTIFF（由矢量栅格化） | J13: 开源✅ 下载✅ 有数据✅ | K13: GHSL-Built：https://ghsl.jrc.ec.europa.eu/download.php； Microsoft-OSM：https://source.coop/vida/google-microsoft-osm-open-buildings/flatgeobuf/by_country/country_iso=CHN/CHN.fgb； 建筑轮廓数据 | L13: Microsoft Building：https://github.com/microsoft/GlobalMLBuildingFootprints(数据处理脚本 + 数据获取指引)； GHSL-Built：https://ghsl.jrc.ec.europa.eu/download.php(建筑高度) | M13: 1. 地理坐标：LAT（十进制度）、LON（十进制度）； 2. 核心字段：BUILDING_HEIGHT（建筑物高度，单位：m）、BUILDING_DENSITY（建筑物密度，单位：栋 /km²）、DEM (0~21.01m)、NDVI (-1~1)、建筑掩码 (0/1)； 3. 辅助字段：CONFIDENCE（检测置信度，0~1 | N13: 1. 缺失值标识：NoData（栅格文件头标注）； 2. 无效值：BUILDING_HEIGHT=-1（无高度估计）、BUILDING_DENSITY=0（无建筑物区域），舟山数据中 BUILDING_HEIGHT 无 -1 无效值（实际为 0~50m），DENSITY=0 代表无建筑区域 | O13: 1. 数据集核心：发布机构 (EU JRC/Microsoft)、数据类型 (矢量转栅格)、坐标参考系 (EPSG:4326)； 2. 字段属性：高度单位 (米)、空间分辨率 (10m/100m)； 3. 质量规则：Microsoft 数据置信度≥0.8 为高质量，GHSL 数据精度与人口密集度正相关，筛选的舟山轮廓数据置信度≥0.8，为高质量；GHSL 高度数据精度与舟山人口密度正相关，符合描述 | P13: 1. 地理特征：经纬度、空间位置； 2. 下垫面特征：建筑物高度、密度（障碍物评估）； 3. 时空特征：静态更新、10-100m 栅格精度 | Q13: ⭐ 简单 | S13: 免费 | T13: 静态/不定期更新 | U13: GHSL: 1975/1990/2000/2015年； Microsoft: 2022年 | V13: 全球(主要城市) | W13: 1. 为风场数值模拟提供三维建筑下垫面特征数据，包括建筑高度、建筑密度、地形高程（DEM）和植被指数（NDVI），用于修正地表粗糙度参数 Z₀、识别城市障碍物分布、模拟建筑对风场的遮挡与尾流效应，提升近地面风场模拟精度，支撑城市风环境评估、台风影响分析及风机选址等应用 | X13: 1. 数据处理成果： - 已完成舟山区域建筑轮廓（Microsoft Open Buildings，2022）、建筑高度（GHSL-BUILT-H，3 arcsec≈100m）、建筑密度（由轮廓矢量计算，栋/km²）的栅格化处理； - 融合 DEM（ASTGTMV003，30m→100m）、NDVI（Sentinel-2 L2A，10m→100m）数据，生成 5 波段 GeoTIFF 输入文件：Zhoushan_WindModel_Input_100m.tif； - 最终数据分辨率 100m，坐标系 EPSG:4326，尺寸 1364×1194，覆盖舟山核心区域（LON:121.9655~123.102°，LAT:29.7382~30.733°）。 2. 验证结论： - 经 Python 代码验证，文件完整、波段数正确（5 个：DEM/NDVI/建筑掩码/高度/密度）、坐标系统一（EPSG:4326）； - DEM 高程范围 0~21.01m，符合舟山海岛/沿海平原地形特征，数值真实有效； - 建筑高度/密度/掩码数据与舟山城市分布匹配，可支撑下垫面障碍物效应模拟。 3. 模型适配性： - 可直接输入风场模型（如 WRF、CFD、WindNinja），用于： ① 基于建筑高度/密度修正地表粗糙度 Z₀； ② 基于建筑掩码标记障碍物区域，模拟风场遮挡/尾流效应； ③ 结合 DEM/NDVI 修正地形/植被对近地面风场的影响。 4. 使用限制与建议： - 原始数据为静态更新（GHSL:2015，Microsoft:2022），无法反映最新城市建设变化； - 偏远海岛数据覆盖稀疏，优先用于舟山城市/近郊风场分析； - 最终数据为 100m 分辨率，若需更高精度（如 10m），可基于原始矢量轮廓重新栅格化。 | Y13: D:\dcsk\knowledge_graph_1014\download_data\geodata\data\舟山\BUILDING-3D\BUILDING-FOOTPRINT\CHN.fgb；D:\dcsk\knowledge_graph_1014\download_data\geodata\data\舟山\BUILDING-3D\BUILDING-HEIGHT\GHS_BUILT_H_AGBH_E2018_GLOBE_R2023A_4326_3ss_V1_0_R6_C31\GHS_BUILT_H_AGBH_E2018_GLOBE_R2023A_4326_3ss_V1_0_R6_C31.tif
A14: =INDEX(数据源对应的文献以及数据使用方法和条目需求!A:B,MATCH(B14,数据源对应的文献以及数据使用方法和条目需求!B:B,0),1) -> 风电场特定数据 | B14: KG-15 | C14: 未使用❌ | D14: 风机位置与布局图 | E14: 空间与地理地形；风电场与机组状态 | F14: 空间与地理地形(离地高度(风机))； 风电场与机组状态(机组布局-风机阵列拓扑、机组气动性能-Cp/Ct曲线) | G14: 时：静态；空：单风机级 | H14: 🔴 必需 | I14: JSON/CSV/Shapefile | J14: 开源⚠️(部分公开) 下载⚠️ 有数据⚠️(多需业主提供) | K14: The Wind Power：https://www.thewindpower.net/ | L14: 1. 公开平台：注册 The Wind Power 账号，查询部分公开风电场布局数据； 2. 核心数据：需向业主提交数据使用申请，提供项目立项证明 + 保密协议，审批通过后获取文件传输权限 | M14: 1. 定位字段：风机编号（Turbine_ID）、lat（纬度，°）、lon（经度，°）、hub_height（轮毂高度，m）、tower_height（塔高，m） 2. 布局 / 性能字段：array_topology（阵列拓扑类型）、row_col_num（行列编号）、Cp_curve（功率系数曲线参数）、Ct_curve（推力系数曲线参数） 3. 质量标识：数据精度标记、坐标系统标记（WGS84 / 地方坐标系） | N14: 1. 定位 / 高度缺失：lat=999.99、lon=999.99、hub_height=999.9、tower_height=999.9 2. 布局 / 性能缺失：array_topology=“Unknown”、Cp_curve=[]、Ct_curve=[] 3. 无效区域标记：非风电场内风机点位标注为 “Invalid” | O14: 1. 数据集核心：风电场风机位置与布局数据集，来源为业主设计文件或 The Wind Power 公开数据库（经校验） 2. 字段元数据： - lat/lon：浮点型，单位 °（坐标系统 WGS84/UTM）；hub_height/tower_height：浮点型，单位 m - array_topology：字符串型；Cp/Ct 曲线：数组型（含风速 - 系数映射关系） 3. 时空基准：时间静态（以最新布局为准），空间为大地坐标系（默认 WGS84 | P14: 地理特征维度：风机经纬度（lat/lon）、轮毂高度、塔高、风电场边界范围 布局特征维度：风机阵列拓扑（行列式 / 随机式）、行列编号、风机间距 性能特征维度：Cp 曲线（功率系数 - 风速）、Ct 曲线（推力系数 - 风速 | Q14: ⭐ 简单 | S14: 需协商 (多需业主提供)（公开平台基础数据免费，高级布局数据需付费订阅） | T14: 静态数据（风机布局变更后同步更新） | U14: 当前状态（自风电场投产至今，随布局调整更新） | V14: 场站级（单风电场完整覆盖，含所有机组及场界范围） | W14: 1. 提供风机精准位置、阵列布局及气动性能数据，用于风场尾流效应模拟、机组布局优化、风资源评估、发电量计算及运维路径规划 | X14: 1. 数据格式：JSON/CSV（字段结构化存储）、Shapefile（地理空间格式，支持地图可视化） 2. 结构：单文件含所有风机信息，按风机编号唯一索引 3. 唯一标识：风电场 ID_风机布局_版本号（示例：WF_ZHOUSHAN_2026V1） 4. 注意事项：需确认坐标系统一致性，业主提供数据需与公开平台交叉校验，Cp/Ct 曲线需匹配风机型号
A15: =INDEX(数据源对应的文献以及数据使用方法和条目需求!A:B,MATCH(B15,数据源对应的文献以及数据使用方法和条目需求!B:B,0),1) -> ERA5相关性数据 | B15: KG-16 | C15: 未使用❌ | D15: 风机SCADA历史数据 | E15: 风电场与机组状态；风速本体及时序特征 | F15: 风电场与机组状态(机组运行模式-启动模式/停机/故障/降载运行/恒功率/恒转速/MPPT/限电、机组硬件状态-变桨系统-桨距角/转子-转子转速/旋转动能/偏航系统-偏航角/对风偏差角/核心部件-机舱温度)； 风速本体及时序特征(历史风速序列) | G15: 时：10min/1s； 空：单风机 | H15: 🔴 必需 | I15: CSV/数据库表 | J15: 开源❌ 下载⚠️(需授权) 有数据⚠️ | K15: 业主提供 | L15: 必须由风电场业主/运维方授权，通过运维系统导出或数据库抽取 | M15: 1. 标识字段：风机编号Turbine_ID、时间Time、场站ID；2. 气象输入：风速WS、风向WD、空气密度、温压湿；3. 运行状态：运行模式、桨距角、转子转速、发电机功率、偏航角、对风偏差、机舱温度、故障码；4. 质量字段：有效标记、数据异常标记 | N15: 1. 数值缺失：WS=99.99、WD=999、功率=99999、转速=9999.9、桨距角=999.9、温度=999.9； 2. 状态缺失：运行模式=Unknown、故障码=9999； 3. 无效标记：有效标记=0/异常标记=1表示无效数据 | O15: 1. 数据集：风机SCADA实时/历史采集数据； 2. 字段：1s/10min采样，单位m/s、°、kW、rpm、℃； 3. 时空基准：本地时间/UTC，单机组单点观测 | P15: 地理特征：单风机位置、场站范围； 机组特征：运行模式、变桨/转子/偏航/温度/故障状态； 功率特征：实时功率、MPPT、限电状态； 时序特征：1s高频/10min统计风速序列 | Q15: ⭐⭐⭐ 困难 | S15: 需协商(需业主授权) | T15: 实时/延迟数分钟 | U15: 风场运行期间(通常3-10年) | V15: 场站级(单风机) | W15: 1. 用于风场预测模型训练、功率验证、故障识别、尾流分析、风速序列拟合、运行状态识别与限电判断 | X15: 1. 记录结构：时间序列结构化存储，单风机一条记录，含运行状态、功率、气象、质量标记； 2. 唯一标识：风机ID + 起始时间 + 结束时间 + 数据版本； 3. 文件名约定：SCADA_Turbine{ID}_{YYYYMMDDHHMM}_{YYYYMMDDHHMM}.csv； 4. 注意事项：数据必须业主授权获取，含大量停机、故障、限电、异常值，使用前必须QC过滤；1s高频数据体积大，常规使用10min统计值。
A16: =INDEX(数据源对应的文献以及数据使用方法和条目需求!A:B,MATCH(B16,数据源对应的文献以及数据使用方法和条目需求!B:B,0),1) -> ERA5相关性数据 | B16: KG-17 | C16: 未使用❌ | D16: 风机功率输出数据 | E16: 风电场与机组状态 | F16: 风电场与机组状态(机组运行模式-功率输出) | G16: 时：10-15min； 空：单风机 | H16: 🔴 必需 | I16: CSV/数据库表 | J16: 开源❌ 下载⚠️ 有数据⚠️ | K16: 业主提供 | L16: 需业主/运维方授权，从SCADA/功率统计系统导出 | M16: 1. 标识字段：风机编号Turbine_ID、时间Time、场站ID； 2. 功率字段：有功功率P、无功功率Q、视在功率S、限电标记、运行状态； 3. 环境字段：风速WS、风向WD、空气密度、温度； 4. 质量标识：有效标记、异常标记、限电标记 | N16: 1. 功率缺失：P=99999、Q=99999、WS=99.99、WD=999； 2. 状态缺失：运行状态=Unknown、限电标记=Unknown； 3. 无效标记：有效标记=0、异常标记=1表示不可用 | O16: 1. 数据集：风机实测功率输出历史数据； 2. 字段：10‑15min统计间隔，单位kW、kVar、m/s、℃； 3. 时空基准：本地时间/UTC，单风机单点观测 | P16: 地理特征：单风机位置、场站范围； 功率特征：有功/无功/视在功率、限电状态、运行模式； 时序特征：10‑15min等间隔功率时序 | Q16: ⭐⭐⭐ 困难 | S16: 需协商(需业主授权) | T16: 实时/延迟数分钟 | U16: 风场运行期间(通常3-10年) | V16: 场站级(单风机) | W16: 1. 用于风功率预测模型训练、实际发电量验证、功率曲线拟合、限电分析、尾流评估、考核指标计算 | X16: 1. 记录结构：时间序列结构化存储，单风机一条记录，以功率为核心字段； 2. 唯一标识：风机ID + 起始时间 + 结束时间 + 数据版本； 3. 文件名约定：Power_Turbine{ID}_{YYYYMM}.csv； 4. 注意事项：必须业主授权获取，数据含停机/故障/限电，使用前必须过滤无效值。
A17: =INDEX(数据源对应的文献以及数据使用方法和条目需求!A:B,MATCH(B17,数据源对应的文献以及数据使用方法和条目需求!B:B,0),1) -> ERA5相关性数据 | B17: KG-18 | C17: 未使用❌ | D17: 风机尾流模型输出 | E17: 风电场与机组状态 | F17: 风电场与机组状态(尾流效应-微观流体效应) | G17: 时：1h； 空：1-5 km 网格/场内网格 | H17: 🟡 推荐 | I17: NetCDF | J17: 模式开源✅ 结果需自跑⚠️ | K17: 基于WRF/专用尾流模型生成 | L17: 需自行搭建/运行尾流模型，无直接下载渠道 | M17: 1. 标识字段：场站ID、网格lon、网格lat、高度height、时间time；2. 尾流字段：风速衰减率、尾流半径、尾流核心区、湍流强度、有效风速；3. 机组字段：风机位置、推力系数Ct、功率损失、尾流交互标记；4. 质量标识：模型收敛标记、有效网格标记 | N17: 1. 尾流缺失：风速=99.99、衰减率=99.99、Ct=99.99、功率损失=999.9；2. 空间缺失：lon=999.99、lat=999.99、height=9999；3. 无效标记：收敛标记=0、有效标记=0为无效计算 | O17: 1. 数据集：风机尾流数值模拟输出结果；2. 字段：小时级输出，单位m/s、km、%、m；3. 时空基准：UTC时间，空间为场内均匀网格 | P17: 地理特征：风电场网格lon/lat/高度、场内空间分布；尾流特征：风速衰减、尾流范围、湍流增强、功率损失、机组交互；时空特征：1h时序、场内1~5km网格分辨率 | Q17: ⭐⭐⭐⭐ 极难 | S17: 高成本(需计算资源+模式运行) | T17: 自定义(需自行运行) | U17: 自定义(取决于输入数据) | V17: 场站级(风场内) | W17: 1. 用于风场尾流效应模拟、机组间干扰分析、功率损失评估、风场布局优化、微观选址及发电量修正 | X17: 1. 记录结构：四维网格结构（时间/经度/纬度/高度），NetCDF标准格式； 2. 唯一标识：风电场ID + 模型版本 + 模拟起止时间； 3. 文件名约定：WakeModel_{WFID}_{YYYYMMDD}.nc； 4. 注意事项：无公开数据，需自行搭建尾流模型运行；依赖风机布局、地形、气象驱动数据；需检查模型收敛性，过滤非收敛网格。
A18: =INDEX(数据源对应的文献以及数据使用方法和条目需求!A:B,MATCH(B18,数据源对应的文献以及数据使用方法和条目需求!B:B,0),1) -> ERA5相关性数据 | B18: KG-19 | C18: 未使用❌ | D18: 边界层高度数据 | E18: 气象与环境 | F18: 气象与环境(大气稳定度-blh指标) | G18: 时：1h； 空：0.25° | H18: 🟡 推荐 | I18: GRIB（二进制）/NetCDF（多维数组）（当前文件：GRIB2） | J18: 开源✅ 下载✅(需注册) 有数据✅ | K18: ERA5：https://cds.climate.copernicus.eu/datasets/reanalysis-era5-single-levels?tab=download | L18: 账号：2072706022@qq.com 密码：Wdl2072706022 | M18: 1. 标识字段：时间 time（1.0h 分辨率，格式 YYYY-MM-DD HH:MM:SS）、网格 lat（0.25° 分辨率，舟山 29.5~31.0°N）、网格 lon（0.25° 分辨率，舟山 121.5~123.5°E）； 2. 核心要素字段：边界层高度 blh（单位：m，物理意义 Boundary layer height）； 3. 元数据字段：数据集 ID（ERA5 hourly data on single levels from 1940 to present）、维护机构（ECMWF）、坐标基准（WGS84 地理坐标系）； 4. 质量标识：数据质控标记（ERA5 严格质控）、有效格点标记（舟山区域格点无缺失） | N18: 1. 数值缺失：blh=NaN（GRIB 格式无显性占位符，实测缺失值占比 0.0%）； 2. 空间异常：lat/lon 超出研究区有效经纬度范围（舟山：29.5~31.0°N/121.5~123.5°E）； 3. 无效标记：blh=0（无物理意义）、blh>5000m（超出合理范围）、NaN（数据缺失）； 4. 合理范围：0~5000m | O18: 1. 元数据字段：数据集 ID（ERA5 hourly data on single levels from 1940 to present）、维护机构（ECMWF 欧洲中期天气预报中心）、坐标基准（WGS84 地理坐标系）、数据来源（ERA5 全球大气再分析数据集）； 2. 字段元数据：单位 (blh：m)、缩放因子 无（原生单位无需换算）、GRIB 版本 2； 3. 时间 / 空间：时间基准 (UTC)、空间覆盖 (全球范围格点，舟山 29.5~31.0°N/121.5~123.5°E)； 4. 数据存储结构：三维数组（time/lat/lon 维度 | P18: 地理特征维度：经纬度（LAT_DEG/LON_DEG，0.25°×0.25° 分辨率，舟山 29.5~31.0°N/121.5~123.5°E）、格点级空间特征（面状覆盖，非站点级）、无独立海拔维度（ERA5 blh 已整合海拔影响）； 气象特征维度：大气稳定度要素（边界层高度 blh）、垂直结构要素（边界层顶高度）、反映近地面大气混合程度； 时空特征维度：小时级时序特征（1.0h 分辨率）、全球格点级空间特征（0.25°×0.25°）、时间连续性（逐小时无间断，ERA5 数据特性） | Q18: ⭐ 简单 | S18: 免费(需注册CDS账号) | T18: 延迟5天 | U18: 1940年至今 | V18: 全球 | W18: 1. 风场预测模型中大气稳定度特征提取； 2. 风资源评估中大气边界层结构分析； 3. 优化风速垂直廓线模拟精度； 4. 评估近地面大气混合层对风机发电效率的影响 | X18: 1. 记录结构：三维数组（time:744, lat:7, lon:9 维度）； 2. 唯一格点 ID：纬度 (0.25° 步长)+ 经度 (0.25° 步长)（示例：29.5°N,121.5°E）； 3. 文件名约定：ERA5_blh_YYYYMMDD_HH.grib（示例：ERA5_blh_20250501_00.grib）； 4. 注意事项：① 舟山区域 blh 数值需结合当地地形高程修正（舟山平均海拔 20~100m）；② 数据经 ECMWF 严格质控无明显异常值（舟山格点无缺失）；③ 免费获取需注册 CDS 账号，数据更新延迟 5 天；④ 当前文件无损坏，可正常解析 | Y18: D:\dcsk\knowledge_graph_1014\download_data\geodata\data\舟山\KG-19\fd3bfa3939a2d7838eb69890f964143d.grib
A19: =INDEX(数据源对应的文献以及数据使用方法和条目需求!A:B,MATCH(B19,数据源对应的文献以及数据使用方法和条目需求!B:B,0),1) -> 大气状态与派生指数数据 | B19: KG-20 | C19: 未使用❌ | D19: 湍流动能(TKE，由摩擦速度/湍流应力估算) | E19: 气象与环境 | F19: 气象与环境(大气稳定度-湍流强度指标) | G19: 时：1-3h； 空：0.25°(ERA5) 或1-5km(WRF) | H19: 🟡 推荐 | I19: NetCDF | J19: 开源✅(ERA5变量或WRF输出) 下载✅/需自跑⚠️ | K19: ERA5/WRF 官网 | L19: 账号：2072706022@qq.com 密码：Wdl2072706022 | M19: 1. 标识字段：时间time（1-3h分辨率）、网格lat（0.25°(ERA5)/1-5km(WRF)分辨率）、网格lon（0.25°(ERA5)/1-5km(WRF)分辨率）； 2. 核心要素字段：摩擦速度u*（单位：m/s）、东向湍流应力τ_u（单位：N/m²）、北向湍流应力τ_v（单位：N/m²）、估算TKE（单位：m²/s²）； 3. 元数据字段：数据集ID（ERA5 hourly data on single levels from 1940 to present/WRF自定义模拟）、维护机构（ECMWF/自定义模拟团队）、坐标基准（WGS84地理坐标系）； 4. 质量标识：数据质控标记（ERA5严格质控/WRF模拟收敛标记）、有效格点标记（目标区域格点无缺失）； | N19: 1. 数值缺失：u*/τ_u/τ_v=NaN（NetCDF格式缺失值统一标识）； 2. 空间异常：lat/lon超出研究区有效经纬度范围； 3. 无效标记：u*=0（无湍流意义）、估算TKE<0（物理意义不合理）、NaN（数据缺失） | O19: 1. 数据集核心元数据：数据集 ID (ERA5 hourly data on single levels from 1940 to present/WRF自定义模拟输出)、维护机构 (ECMWF 欧洲中期天气预报中心/自定义模拟团队)、数据来源 (ERA5全球大气再分析数据集/WRF数值模拟输出)； 2. 字段元数据：单位 (u*：m/s、τ_u/τ_v：N/m²、TKE：m²/s²)、缩放因子 无（原生单位无需换算）、格式版本 (NetCDF4)； 3. 时间 / 空间：时间基准 (UTC)、空间覆盖 (全球范围格点(ERA5)/自定义区域格点(WRF)) | P19: 地理特征维度：经纬度（LAT_DEG/LON_DEG，0.25°×0.25°(ERA5)/1-5km×1-5km(WRF)分辨率）、格点级空间特征（面状覆盖，非站点级）、无独立海拔维度（近地面湍流特征）； 气象特征维度：湍流强度要素（摩擦速度u*）、湍流应力要素（τ_u/τ_v）、估算湍流动能（TKE≈0.5×u*²）、大气稳定度表征； 时空特征维度：小时级时序特征（1-3h分辨率）、全球/自定义格点级空间特征（0.25°×0.25°(ERA5)/1-5km×1-5km(WRF)）、时间连续性（逐小时无间断(ERA5)/自定义(WRF)） | Q19: ⭐~⭐⭐⭐⭐ | S19: 免费(ERA5) / 高成本(WRF) | T19: 延迟5天(ERA5) / 自定义(WRF) | U19: 1940年至今(ERA5) / 自定义(WRF) | V19: 全球(ERA5) / 自定义(WRF) | W19: 1. 风场预测模型湍流强度特征提取； 2. 风资源评估大气边界层湍流结构分析； 3. 优化风机尾流模拟中湍流耗散参数； 4. 评估湍流强度对风机发电效率与载荷的影响； | X19: 1. 记录结构：三维数组（time/lat/lon维度）； 2. 唯一格点 ID：纬度(0.25°/1-5km步长)+经度(0.25°/1-5km步长)； 3. 文件名约定：ERA5_TKE_YYYYMMDD_HH.nc(ERA5)/WRF_TKE_YYYYMMDD_HH.nc(WRF)； 4. 注意事项：① 目标区域 TKE 需由 ERA5 替代变量估算（核心公式：TKE ≈ 0.5 × u*²）；② ERA5 数据经 ECMWF 严格质控无明显异常值，WRF 数据需验证模拟收敛性；③ ERA5 免费获取需注册 CDS 账号（数据延迟 5 天），WRF 需自跑模拟（高算力成本）；④ 数据格式为 NetCDF，可通过 xarray/netCDF4 读取后处理；
A20: =INDEX(数据源对应的文献以及数据使用方法和条目需求!A:B,MATCH(B20,数据源对应的文献以及数据使用方法和条目需求!B:B,0),1) -> ERA5相关性数据 | B20: KG-21 | C20: 未使用❌ | D20: 垂直风切变指数 | E20: 风速本体及时序特征 | F20: 风速本体及时序特征(湍流强度/风切变) | G20: 时：1h (ERA5)；空：0.25° 网格 | H20: 🟡 推荐 | I20: 源数据 CSV/TXT/NetCDF； 指数为工程计算字段 | J20: 开源✅(ERA5)；下载✅ | K20: ERA5：https://cds.climate.copernicus.eu/datasets/reanalysis-era5-single-levels?tab=download | L20: 账号：2072706022@qq.com 密码：Wdl2072706022 | M20: 1. 标识字段：时间 time（1h 分辨率）、网格 lat（0.25°）、网格 lon（0.25°）、高度层 height（10m/100m）； 2. 核心要素字段：u10、v10、u100、v100（单位：m s⁻¹）、垂直风切变指数（单位：s⁻¹ 或 m/s/100m）； 3. 元数据字段：数据集 ID（ERA5 hourly data on single levels from 1940 to present）、维护机构（ECMWF 欧洲中期天气预报中心）、坐标基准（WGS84 地理坐标系）； 4. 质量标识：数据质控标记（ERA5 严格质控）、有效格点标记（目标区域无缺失）； | N20: 1. 数值缺失：缺失值：99.99 / 999.9 / NaN；缺失值占比 0.0%； 2. 空间异常：lat/lon超出目标区域、高度层缺失； 3. 无效标记：风速 < 0、风切变指数 < 0、风速 = 0、Na） | O20: 1. 数据集核心元数据：数据集 ID (ERA5 hourly data on single levels from 1940 to present)、维护机构 (ECMWF 欧洲中期天气预报中心)、数据来源 (ERA5 再分析)； 2. 字段元数据：单位 (风速：m/s、风切变指数：s⁻¹)、缩放因子 无（原生单位无需换算）、格式版本 (GRIB2)； 3. 时间 / 空间：时间基准 (UTC)、空间覆盖 (全球网格 (ERA5)) | P20: 地理特征维度：网格经纬度（LAT_DEG/LON_DEG，0.25°×0.25° 分辨率）、高度层分布（10m/100m）、网格空间特征； 气象特征维度：风速垂直梯度、垂直风切变强度、湍流强度关联表征； 时空特征维度：1h 时序特征、网格级空间特征（0.25°×0.25°）、时间连续性（逐小时无间断 (ERA5)） | Q20: ⭐⭐~⭐⭐⭐ | S20: 免费 (ERA5) | T20: 延迟 5 天 (ERA5) | U20: 1940 年至今 (ERA5) | V20: 全球(ERA5) | W20: 1. 风场预测模型垂直风切变特征提取； 2. 风资源评估风机载荷与安全工况分析； 3. 优化风速垂直廓线拟合精度； 4. 评估风切变对风机发电效率与疲劳寿命的影响； | X20: 1. 记录结构：三维数组（time/lat/lon 维度）；2. 唯一标识：网格 ID + 高度层 + 时间戳；3. 文件名约定：ERA5_Shear_YYYYMMDD_HH.nc；4. 注意事项：① 垂直风切变由多层风速计算得到（核心公式：Shear = (V₁₀₀ - V₁₀) /ln (100/10)）；② ERA5 需多层风速数据；③ 数据经质控，缺失值占比 0.0%；④ ERA5 免费需注册 CDS 账号，延迟 5 天； | Y20: D:\dcsk\knowledge_graph_1014\download_data\geodata\data\舟山\KG-20-21-22\87aa950f2c788dc9592506e5548116b8.grib
A21: =INDEX(数据源对应的文献以及数据使用方法和条目需求!A:B,MATCH(B21,数据源对应的文献以及数据使用方法和条目需求!B:B,0),1) -> ERA5相关性数据 | B21: KG-22 | C21: 未使用❌ | D21: 大气稳定度指数 | E21: 气象与环境 | F21: 气象与环境(大气稳定度-Richardson数/Monin-Obukhov长度/Pasquill稳定度分类) | G21: 时：1h (ERA5)；空：0.25° 网格 | H21: 🟡 推荐 | I21: 源数据 NetCDF/TXT； 指数为工程计算字段 | J21: ERA5/探空开源✅ 下载✅ 有数据✅ | K21: ERA5：https://cds.climate.copernicus.eu/； 探空：http://weather.uwyo.edu/upperair/sounding.html | L21: 账号：2072706022@qq.com 密码：Wdl2072706022 | M21: 1. 标识字段：时间 time（1h 分辨率）、网格 lat（0.25°）、网格 lon（0.25°）、高度层 height； 2. 核心要素字段：2 米温度（单位：K）、10 米风速（u/v 分量，单位：m/s）、地表压力（单位：Pa）、Richardson 数、Monin-Obukhov 长度、Pasquill 稳定度等级； 3. 元数据字段：数据集 ID（ERA5 hourly data on single levels from 1940 to present）、维护机构（ECMWF 欧洲中期天气预报中心）、坐标基准（WGS84 地理坐标系）； 4. 质量标识：数据质控标记（ERA5 严格质控）、有效格点标记（目标区域无缺失）； | N21: 1. 数值缺失：缺失值：NaN / 999.9；缺失占比 0.0%； 2. 空间异常：lat/lon超出目标区域、廓线高度层不连续； 3. 无效标记：温度 <100K 或>400K；NaN、风速 < 0、地表压力 < 80000Pa 或 > 110000Pa、Richardson 数无物理极值、稳定度等级超出范围（A-F）、NaN（数据缺失） | O21: 1. 数据集核心元数据：数据集 ID (ERA5 hourly data on single levels from 1940 to present)、维护机构 (ECMWF 欧洲中期天气预报中心)、数据来源 (ERA5 再分析)； 2. 字段元数据：单位 (温度：K、风速：m/s、地表压力：Pa、Monin-Obukhov 长度：m)、缩放因子 无（原生单位无需换算）、格式版本 (GRIB2)； 3. 时间 / 空间：时间基准 (UTC)、空间覆盖 (全球网格 (ERA5)) | P21: 地理特征维度：网格经纬度（LAT_DEG/LON_DEG，0.25°×0.25° 分辨率）、高度层分布（边界层）、网格空间特征；气象特征维度：温度垂直梯度、风速垂直梯度、Richardson 数、Monin-Obukhov 长度、Pasquill 稳定度分类；时空特征维度：1h 时序特征、网格级空间特征（0.25°×0.25°）、时间连续性（逐小时无间断 (ERA5)） | Q21: ⭐⭐ 中等 | S21: 免费(需注册) | T21: 延迟5天(ERA5) | U21: 1940年至今(ERA5) | V21: 全球(ERA5) | W21: 1. 风场预测模型大气稳定度分类特征提取； 2. 风资源评估边界层湍流结构分析； 3. 优化尾流模型与湍流扩散参数； 4. 评估大气稳定度对风场波动与发电量的影响； | X21: 1. 记录结构：三维数组（time/lat/lon 维度）； 2. 唯一标识：网格 ID + 时间戳； 3. 文件名约定：ERA5_Stab_YYYYMMDD_HH.nc； 4. 注意事项：① 稳定度指数由 Richardson 数、Monin‑Obukhov 长度计算；② ERA5 数据可作为输入；③ 数据经严格质控，缺失值占比 0.0%；④ 免费需注册，ERA5 延迟 5 天； | Y21: D:\dcsk\knowledge_graph_1014\download_data\geodata\data\舟山\KG-20-21-22\87aa950f2c788dc9592506e5548116b8.grib
A22: =INDEX(数据源对应的文献以及数据使用方法和条目需求!A:B,MATCH(B22,数据源对应的文献以及数据使用方法和条目需求!B:B,0),1) -> ERA5相关性数据 | B22: KG-23 | C22: 未使用❌ | D22: 对流可用位能(CAPE) | E22: 气象与环境 | F22: 气象与环境(大气稳定度-对流指标) | G22: 时：1h；空：0.25° 网格 | H22: 🟡 推荐 | I22: NetCDF/GRIB | J22: 开源✅ 下载✅ 有数据✅ | K22: ERA5：https://cds.climate.copernicus.eu/ | L22: 账号：2072706022@qq.com 密码：Wdl2072706022 | M22: 1. 标识字段：时间 time（1h 分辨率）、网格 lat（0.25° 分辨率）、网格 lon（0.25° 分辨率）； 2. 核心要素字段：对流可用位能 CAPE（单位：J/kg）； 3. 元数据字段：数据集 ID（ERA5 hourly data on single levels from 1940 to present）、维护机构（ECMWF 欧洲中期天气预报中心）、坐标基准（WGS84 地理坐标系）； 4. 质量标识：数据质控标记（ERA5 严格质控）、有效格点标记（目标区域格点无缺失）； | N22: 1. 数值缺失：缺失值：NaN；缺失占比 0.0%（NetCDF/GRIB格式缺失值统一标识）； 2. 空间异常：lat/lon超出研究区有效经纬度范围； 3. 无效标记：CAPE<0（物理意义不合理）、CIN>0（无对流抑制意义）、NaN（数据缺失） | O22: 1. 数据集核心元数据：数据集 ID (ERA5 hourly data on single levels from 1940 to present)、维护机构 (ECMWF 欧洲中期天气预报中心)、数据来源 (ERA5 全球大气再分析数据集)； 2. 字段元数据：单位 (CAPE：J/kg)、缩放因子 无（原生单位无需换算）、格式版本 (GRIB2)； 3. 时间 / 空间：时间基准 (UTC)、空间覆盖 (全球范围格点) | P22: 地理特征维度：经纬度（LAT_DEG/LON_DEG，0.25°×0.25° 分辨率）、格点级空间特征（面状覆盖，非站点级）；气象特征维度：对流不稳定指标（CAPE）、大气对流潜力表征；时空特征维度：小时级时序特征（1.0h 分辨率）、全球格点级空间特征（0.25°×0.25°）、时间连续性（逐小时无间断） | Q22: ⭐ 简单 | S22: 免费(需注册CDS账号) | T22: 延迟5天 | U22: 1940年至今 | V22: 全球 | W22: 1. 风场预测模型对流不稳定特征提取； 2. 风资源评估强对流天气风险分析； 3. 优化极端风况预测与风机安全控制； 4. 评估对流活动对风电场出力稳定性的影响； | X22: 1. 记录结构：三维数组（time/lat/lon 维度）； 2. 唯一格点 ID：纬度 (0.25° 步长)+ 经度 (0.25° 步长)； 3. 文件名约定：ERA5_CAPE_YYYYMMDD_HH.nc； 4. 注意事项：① CAPE 为 ERA5 直接输出变量，表征对流潜力（数值范围 0.00~140.62 J/kg）；② 数据经 ECMWF 严格质控无异常，缺失值占比 0.0%；③ 免费获取需注册 CDS 账号，数据延迟 5 天； | Y22: D:\dcsk\knowledge_graph_1014\download_data\geodata\data\舟山\KG-20-21-22\87aa950f2c788dc9592506e5548116b8.grib
A23: =INDEX(数据源对应的文献以及数据使用方法和条目需求!A:B,MATCH(B23,数据源对应的文献以及数据使用方法和条目需求!B:B,0),1) -> 时空上下文特征数据 | B23: KG-24 | C23: 未使用❌ | D23: 经纬度与海拔 | E23: 空间与地理地形 | F23: 空间与地理地形(经度、纬度、海拔-场址海拔基准) | G23: 时：静态；空：站点/风机级 | H23: 🔴 必需 | I23: CSV/DB(坐标表)+GeoTIFF(DEM) | J23: 开源✅(DEM) 坐标自有数据；有数据✅ | K23: DEM 数据：ASTGTM 30m 高程数据（WGS84，EPSG:4326），已覆盖舟山全域； 经纬度：从舟山研究区（121.9655~123.102°E，29.7382~30.733°N）内风机/测点位置获取，或通过地图拾取获得。 | M23: 1. 经度 Lon（十进制度）； 2. 纬度 Lat（十进制度）； 3. 海拔高度（单位：m） | N23: 1. 缺失值：无（站点级必须配置）； 2. 无效海拔：负值（近海区域需修正） | O23: 1. 数据类型：静态空间位置数据； 2. DEM坐标系：WGS84（EPSG:4326）； 3. 精度：DEM 30m，坐标GPS级 | P23: 1. 空间定位：确定风机/测点地理位置； 2. 地形基准：提供海拔高度，用于风场模型高度参照； 3. 时空特征：静态不变 | Q23: ⭐ 简单 | S23: 免费(DEM) / 自有数据(GPS) | T23: 静态数据 | U23: DEM:2000年至今； GPS：当前 | V23: 全球(DEM) / 站点级(GPS) | W23: 1. 提供风机 / 测点的精准空间定位和海拔基准 2. 作为风场模型的地形高度参照，支撑风场模拟中海拔校正、场址位置匹配，保障风场预测的空间准确性 | X23: 经纬度来源于风机 / 测点 GPS 坐标或地图拾取，确保站点级空间定位精准； 2. 海拔从 ASTGTM 30m DEM 数据（WGS84 坐标系，EPSG:4326）中提取对应点位高程，近海区域需排查并修正负值无效海拔； 3. 数据为静态，作为风场模型的基础空间基准数据，无时间变化
A24: =INDEX(数据源对应的文献以及数据使用方法和条目需求!A:B,MATCH(B24,数据源对应的文献以及数据使用方法和条目需求!B:B,0),1) -> 时空上下文特征数据 | B24: KG-25 | C24: 未使用❌ | D24: 时间特征（年、月、日、时、日序） | E24: 风速本体及时序特征 | F24: 风速本体及时序特征(时间嵌入特征) | G24: 时：与原始序列一致；空：同站点/风机 | H24: 🔴 必需 | I24: 工程计算字段（CSV/Parquet/DB 列） | J24: —（从时间戳计算）从时间戳计算） 无需外部数据源，从时间戳自动生成 | K24: — | M24: 1. 年； 2. 月； 3. 日； 4. 时； 5. 日序DayOfYear | N24: 1. 无缺失值（时间戳完整即可生成）； 2. 异常值：时间不连续、时间戳错误需清洗 | O24: 1. 特征类型：时间嵌入特征； 2. 计算方式：从datetime时间戳提取； 3. 无单位 | P24: 1. 时序特征：提供周期信息（日/月/季节/年际）； 2. 模型输入：作为机器学习/风场模型的时间维度特征； 3. 时空特征：与风速序列时间同步 | Q24: ⭐ 简单 | S24: 免费(工程计算) | T24: 实时(从时间戳提取) | U24: 无限制(取决于原始数据时间范围) | V24: 无限制(适用于所有数据) | W24: 1. 提取风速时间序列的时间嵌入特征，提供日、月、季节、年际等周期信息 2. 作为风场预测模型（机器学习 / 数值模拟）的时间维度输入，提升风速预测精度。 | X24: 无需外部下载数据源，通过工程计算从原始风速时间戳（datetime）中自动提取，与风速序列时间保持同步； 2. 提取过程中需清洗时间不连续、时间戳错误等异常值，确保特征有效性； 3. 特征无单位，实时提取生成，适用所有风场站点 / 风机的时序模拟场景
A25: =INDEX(数据源对应的文献以及数据使用方法和条目需求!A:B,MATCH(B25,数据源对应的文献以及数据使用方法和条目需求!B:B,0),1) -> ERA5相关性数据 | B25: KG-26 | C25: 未使用❌ | D25: 天气形势分型 | E25: 本体外扩展 | F25: 本体外扩展(天气形势分型-聚类特征) | G25: 时：1h(随NWP)； 空：大尺度场/站点映射 | H25: 🟢 可选 | I25: 工程计算字段 | J25: —（从 NWP 聚类得到） | K25: — | L25: 开源✅(依赖ERA5)；需聚类计算 从NWP/ERA5再分析数据聚类得到 | M25: 1. 标识字段：时间time（1h分辨率）、格点lat/lon（0.25°）； 2. 核心要素字段：天气型编号、环流类型、主导系统类型； 3. 元数据字段：数据集ID（ERA5 hourly data）、维护机构（ECMWF）、坐标基准（WGS84）； 4. 质量标识：基于ERA5严格质控，格点全覆盖无缺失 | N25: 1. 数值缺失：天气型编号=-99、NaN； 2. 空间异常：lat/lon超出29.5~31.0°N、121.5~123.5°E； 3. 无效标记：天气型编号<0或超出分类范围、时间不连续 | O25: 1. 数据集核心元数据：数据集ID（ERA5 hourly data on single levels from 1940 to present）、维护机构（ECMWF）、数据来源（ERA5再分析）； 2. 字段元数据：单位（无/分型编号）、缩放因子无、格式版本（工程计算字段）； 3. 时间/空间：时间基准UTC、空间覆盖全球格点 | P25: 地理特征维度：格点经纬度（0.25°×0.25°）、大尺度环流场空间特征、区域映射特征；气象特征维度：环流类型、主导天气系统、气压场特征、稳定度特征；时空特征维度：1h时序、大尺度空间场、时间连续性（逐小时） | Q25: ⭐⭐ 中等 | S25: 免费(需NWP数据+聚类算法) | T25: 延迟5天(取决于NWP) | U25: 1940年至今(取决于NWP数据) | V25: 全球(取决于NWP覆盖) | W25: 1. 风场预测大尺度环流背景特征输入； 2. 提升风速/风电功率预测鲁棒性； 3. 按天气型分场景建模； 4. 异常天气预警辅助 | X25: 1. 记录结构：时序+格点二维； 2. 唯一标识：格点ID+时间戳； 3. 文件名约定：WeatherType_YYYYMMDD.nc； 4. 基于ERA5温、压、风、高度场聚类得到天气型
A26: =INDEX(数据源对应的文献以及数据使用方法和条目需求!A:B,MATCH(B26,数据源对应的文献以及数据使用方法和条目需求!B:B,0),1) -> 历史与误差信息数据 | B26: KG-27 | C26: 未使用❌ | D26: 基础模型/历史预测误差 | E26: 本体外扩展 | F26: 本体外扩展(历史预测误差-MOS方法/模型误差统计) | G26: 时：按统计周期/或逐时； 空：场站/风机级 | H26: 🟡 推荐 | I26: CSV/Parquet/数据库表 | J26: —（模型内部生成） | K26: — | L26: 开源✅(模型内部生成) 模型预测输出+ERA5真值计算 | M26: 1. 标识字段：时间time（1h）、场站/格点lat/lon；2. 核心要素字段：预测风速、观测/真值风速、绝对误差、相对误差、误差符号；3. 元数据字段：模型版本、坐标基准WGS84；4. 质量标识：有效预测时段标记、异常误差过滤 1. 数值缺失：误差=999/NaN；2. 时间异常：预测时间超前/滞后超阈值；3. 无效标记：误差绝对值超合理范围、无对应真值 | N26: 1. 数值缺失：误差=999/NaN； 2. 时间异常：预测时间超前/滞后超阈值； 3. 无效标记：误差绝对值超合理范围、无对应真值 | O26: 1. 数据集核心元数据：来源为预测模型输出+ERA5真值、维护机构（项目内部）； 2. 字段元数据：单位（m/s、无维）、缩放因子无； 3. 时间/空间：时间基准UTC、空间覆盖本项目格点 | P26: 地理特征维度：场站/格点经纬度、区域空间分布特征；气象特征维度：风速误差、稳定度相关误差、天气型相关偏差；时空特征维度：逐小时误差时序、日内/周内/月内误差周期 | Q26: ⭐⭐ 中等 | S26: 免费(模型内部生成) | T26: 实时(随模型预测) | U26: 模型运行期间 | V26: 场站级(取决于模型应用范围) | W26: 1. MOS模型校正输入； 2. 预测偏差修正； 3. 模型效果评估； 4. 分场景误差学习 | X26: 1. 记录结构：时间+站点/格点二维； 2. 唯一标识：场站ID+预测时间； 3. 文件名约定：ModelError_YYYYMMDD.csv； 4. 误差由预测场与ERA5真值计算得到
A27: =INDEX(数据源对应的文献以及数据使用方法和条目需求!A:B,MATCH(B27,数据源对应的文献以及数据使用方法和条目需求!B:B,0),1) -> ERA5相关性数据 | B27: KG-28 | C27: 未使用❌ | D27: 多模式集合预报 | E27: 气象与环境 + 本体外扩展 | F27: 气象与环境 (整体气象背景场：GFS 0.25° 风场 / 气压场 / 温度场)；本体外扩展 (预测不确定性 - 集合特征：风速集合离散度 / 概率指标) | G27: 时：1h(典型)；空：0.25°（GFS 原始分辨率） | H27: 🟡 推荐 | I27: GRIB/NetCDF (原始)；CSV/Parquet (整理后) | J27: NWP 开源✅/部分付费；有数据✅ | K27: ERA5：https://cds.climate.copernicus.eu/； GFS：https://nomads.ncep.noaa.gov/； ECMWF HRES：见上 | M27: 1. 标识字段：时间 time（1h）、集合成员（GFS 集合预报成员）、lat/lon（0.25°）； 2. 核心要素字段：集合风速均值、集合离散度、风速上下限、概率指标；u10/v10（10m 风分量）、t2m（2m 气温）、sp（表面气压）、wind_speed（风速）、wind_dir（风向） 3. 元数据字段： 模式来源（GFS）、分辨率（0.25°）、坐标基准 WGS84； 4. 质量标识：集合成员完整性、异常值过滤（风速 < 0 / 离散度为负 / 时间不连续已过滤 | N27: 1. 数值缺失：风速 = 99.99/NaN；（已处理：缺失值填充 / 剔除）； 2. 空间异常：超出本项目经纬度范围； 3. 无效标记：风速 < 0、离散度为负、时间不连续；（已处理：无效值标记为 NaN 并过滤） | O27: 1. 数据集核心元数据：来源 GFS、维护机构 NCEP（美国国家环境预报中心）； 2. 字段元数据： 单位：u10/v10/wind_speed (m/s)、sp (Pa)、t2m (K)、wind_dir (°)；缩放因子无；格式 GRIB2/NetCDF； 3. 时间/空间：时间基准 UTC、空间基准全球 0.25° 格点 | P27: 地理特征维度：0.25°×0.25° 格点经纬度、大尺度气象场空间结构（GFS 全球格点→舟山区域裁剪； 气象特征维度：集合风速场、气压场、温度场、离散度 / 不确定性（u10/v10/t2m/sp/wind_speed/wind_dir）； 时空特征维度：1h 时序、集合预报时间序列、空间一致性（GFS 1h 更新频率，舟山区域空间一致性校验） | Q27: ⭐⭐ 中等 | S27: 免费(ERA5/GFS) / 付费(ECMWF HRES) | T27: 延迟5天(ERA5) / 实时(GFS) / 延迟数小时(HRES) | U27: 1940年至今(ERA5) / 近10年(GFS) / 近10-15年(HRES) | V27: 全球 | W27: 1. 风场概率预测； 2. 预测不确定性评估； 3. 多模式融合校正； 4. 极端风况风险预警； 5. 舟山区域风速 / 气温空间分布分析； | X27: 1. 记录结构：集合成员×time×lat×lon； 2. 唯一标识：模式+成员+时间+格点； 3. 文件名约定：MultiModel_YYYYMMDD.nc； 4. 支持ERA5/GFS/ECMWF多源融合输入 | Y27: D:\dcsk\knowledge_graph_1014\download_data\geodata\data\舟山\KG-28\gfs_full\gfs.t06z.pgrb2.0p25.f000
A28: =INDEX(数据源对应的文献以及数据使用方法和条目需求!A:B,MATCH(B28,数据源对应的文献以及数据使用方法和条目需求!B:B,0),1) -> ERA5相关性数据 | B28: AIA-1090 | C28: 使用✅ | D28: NOAA GSOD全球逐日汇总数据 | E28: 气象与环境； 相邻/上游测风站数据 | F28: 气象与环境(数据源类型-实测值)； 相邻/上游测风站数据(历史风速) | G28: 时：日（GMT/UTC 0000Z-2359Z 汇总）；空：站点级（全球 9000 + 站点） | H28: 🟡 推荐 | I28: ASCII/CSV/TXT（压缩包格式：tar.gz）；核心数据源：ISD/USAF DATSAV3 | J28: 开源✅ 下载✅ 有数据✅ | K28: NOAA GSOD：https://www.ncei.noaa.gov/data/global-summary-of-the-day/archive/ | L28: 陈林老师已经完成1929-2025的数据下载（天翼云） | M28: 1. 站点基础信息： STATION（站点编号，WMO/DATSAV3 格式）、DATE（观测日期，mm/dd/yyyy，GMT 基准）、LATITUDE（纬度，十进制度，南半球负值）、LONGITUDE（经度，十进制度，西半球负值）、ELEVATION（海拔，米）、NAME（站点名称）； 2. 气象要素： TEMP（日平均气温，°F×0.1）、MAX（日最高气温，°F×0.1）、MIN（日最低气温，°F×0.1）、DEWP（日平均露点，°F×0.1）、SLP（日平均海平面气压，mb×0.1）、STP（日平均站点气压，mb×0.1）、WDSP（日平均风速，knots×0.1）、MXSPD（日最大持续风速，knots×0.1）、GUST（日最大阵风，knots×0.1）、VISIB（日平均能见度，英里 ×0.1）、PRCP（日累计降水量，英寸 ×0.01）、SNDP（雪深，英寸 ×0.1）、FRSHTT（6 位天气现象标识，从左到右依次为：F 雾、R 雨、S 雪、H 冰雹、T 雷暴、T 龙卷风 / 漏斗云；1 = 发生，0 = 未发生 / 未报告）、PRCP_ATTRIBUTES（降水量属性代码，A-I 分别对应不同报告频次与数据完整性） | N28: 1. 标准缺失值：温度 / 气压类 9999.9；风 / 能见度类 999.9/999；降水量 99.99；雪深 999.9； 2. PRCP=0：确认无实测降水（含微量）； 3. PRCP_ATTRIBUTES 代码 H：报告 0 值但小时观测有降水（数据不完整）； 4. PRCP_ATTRIBUTES 代码 I：当日无任何降水报告（仍可能存在未报告降水）； 5. 缺失值含义：99.99/999.9 代表未报告 / 缺失，而非无数据；部分站点无数据时填充 999.9 而非 0 | O28: 1. 数据集核心： 发布机构 (NOAA National Centers for Environmental Information, NCEI)、数据来源 (ISD/USAF DATSAV3)、时间基准 (GMT/UTC 0000Z-2359Z)、版本 (V8)、更新频率 (观测日后 1-2 天)； 2. 字段属性： TEMP/MAX/MIN 单位 (°F×0.1)、SLP/STP 单位 (mb×0.1)、WDSP/MXSPD/GUST 单位 (knots×0.1)、VISIB 单位 (英里 ×0.1)、PRCP 单位 (英寸 ×0.01)、SNDP 单位 (英寸 ×0.1)； 3. 质量规则： 每日至少 4 次有效观测生成日数据；存在单位转换舍入误差；日极值 / 累计值可能跨日历日 | P28: 1. 地理特征维度： 全球站点分布、经纬度 / 海拔属性、站点编号唯一标识； 2. 气象特征维度： 温湿要素（气温、露点）、气压要素（海平面 / 站点气压）、风要素（平均 / 最大持续 / 阵风）、能见度要素、降水 / 积雪要素、天气现象要素（雾 F、雨 R、雪 S、冰雹 H、雷暴 T、龙卷风 / 漏斗云 T，通过 FRSHTT 6 位编码标识））； 3. 时空特征维度： 日级 GMT 汇总时序、1929 年至今长期连续时序、全球站点级空间覆盖 | Q28: ⭐⭐ 中等 | S28: 免费 | T28: 延迟1-2天 | U28: 1929 年至今（1973 年至今数据最完整） | V28: 全球 9000 + 气象站点（覆盖纬度 90°S~90°N、经度 180°W~180°E） | W28: 1. 风资源评估中历史风速/风况统计分析； 2. 气象背景场补充与测风塔数据校验； 3. 长期气候趋势分析与极端天气事件复盘； 4. 风场预测模型历史误差校准与边界条件优化； 5. 相邻/上游站点气象要素关联分析，提升风场预测精度； 6. 温压湿等气象要素与风速相关性研究。 | X28: 1. 数据属性：GSOD 为日级汇总数据，源自 ISD/USAF DATSAV3 小时观测，需每日≥4 次有效观测； 2. 文件名规范：年度.tar.gz（如 2025.tar.gz），数据基于 GMT/UTC 0000Z-2359Z 汇总； 3. 时间特性：日极值 / 累计值（降水、阵风、积雪）可能跨相邻日历日； 4. 使用限制：非美国站点数据仅限科研 / 教育，禁止商业再分发 / 出口；美国站点无此限制； 5. 数据特征：部分能见度值存在聚集（如 10 英里），因站点报告上限所致； 6. FRSHTT 编码示例：101000 表示当日有雾和雪，无雨、冰雹、雷暴、龙卷风； 7. PRCP_ATTRIBUTES 代码 A-I 用于标识降水报告频次与数据完整性，需结合 PRCP 值共同解读； 8. 部分站点能见度值存在聚集（如 10 英里），因站点报告上限所致 | Y28: 天翼云：/home/admin/data_set/mvp_data/noaa_gsd_samples
A29: =INDEX(数据源对应的文献以及数据使用方法和条目需求!A:B,MATCH(B29,数据源对应的文献以及数据使用方法和条目需求!B:B,0),1) -> ERA5相关性数据 | B29: AIA-1091 | C29: 使用✅ | D29: 中国第一代全球陆面再分析产品（CMA-RA/Land）- 大气驱动融合产品 | E29: 气象与环境；相邻/上游测风站数据 | F29: 气象与环境(数据源类型-实测值)；相邻/上游测风站数据(历史风速) | G29: 时：3h（每日 8 个时次）；空：约 34km（高斯网格 1152×576） | H29: 🔴 必需 | I29: GRIB（标准气象格点格式） | J29: 开源✅ 下载✅(需注册) 有数据✅ | K29: 中国气象数据网：https://data.cma.cn/ | M29: 1. 基础标识信息： TIME（观测时间，UTC，3h 间隔）、LATITUDE（纬度）、LONGITUDE（经度）、GRID_ID（网格编码）、PRODUCT_TYPE（大气驱动融合产品）； 2. 气象要素： 近地面要素：T2M（2 米气温）、SPFH2M（2 米比湿）、UGRD10M（10 米 U 风）、VGRD10M（10 米 V 风）、PRCP（降水率）； 关联陆面要素（配套产品）：TS（地表温度）、SOIL_T（各层土壤温度）、SOIL_M（各层土壤湿度 | N29: 1. 无统一数字缺失标记，采用 GRIB 原生缺失值标识； 2. 全球网格全域覆盖，无空间缺失区域； 3. 0 值为有效模拟结果（如无降水时 PRCP=0），非缺失； 4. 样例数据仅开放中国区域（bbox [60.0, 0.0, 160.0, 65.0]），其他区域需商业授权获取 | O29: 1. 数据集核心： 发布机构（国家气象信息中心 / 中国气象局）、数据类型（第一代全球陆面再分析数据）、核心模型（Noah 3.3 陆面模式）、同化技术（四维集合变分混合同化）； 2. 字段属性： 时间分辨率（3h）、空间分辨率（34km）、垂直结构（土壤 4 层：0-0.1/0.1-0.4/0.4-1.0/1.0-2.0m）、数据基准（UTC）； 3. 质量规则： 基于多源观测同化生成，数据质量与国际第三代再分析产品相当；500hPa 位势高度误差低于早期国外产品；更新延迟 6.5-9 小时 | P29: 1. 地理特征维度： 全球网格覆盖、34km 等分辨率分布、中国区域样例开放； 2. 气象特征维度： 近地面温湿风要素、降水要素、配套陆面状态变量（土壤温湿度、地表通量等）； 3. 时空特征维度： 3h 高频时序特征、1979 年至今连续时序、网格级空间特征、多圈层（大气 - 陆面）关联特征 | Q29: ⭐⭐ 中等 | S29: 免费（中国区域样例数据，科研/个人使用）；商业/大批量数据需授权付费 | T29: 延迟 1-2 天（观测日后 1-2 天内更新） | U29: 1979 年1月1日至今（持续更新） | V29: 全球（样例数据开放中国范围下载） | W29: 1. 风资源评估中历史风速统计与风场模拟； 2. 陆面 - 水文 - 生态模型驱动场，支撑水循环 / 碳循环模拟； 3. 长期气候变化趋势分析与极端天气事件复盘； 4. 数值预报模式初始场与边界条件补充； 5. 农业 / 新能源 / 水资源管理等跨行业专业气象服务； 6. 相邻 / 上游区域气象要素关联分析，提升局地预测精度 | X29: 1. CMA-RA 是我国首套自主全球陆面再分析产品，打破欧美产品依赖，质量与 JRA-55 等国际产品相当； 2. 产品分大气驱动融合产品（核心）与陆面产品（配套），数据格式为 GRIB，天翼云存储路径：/home/admin/data_set/mvp_data/CMA-RA； 3. 数据通过中国气象数据网注册获取，样例数据（中国区域）免费，大批量 / 商业使用需授权； 4. 2024 年升级版本 CMA-RA V1.5 分辨率提升至 10km，更新频率达逐小时； 5. 垂直方向土壤分 4 层，配套陆面产品含土壤温湿度、地表通量等约 30 个变量 | Y29: 天翼云：/home/admin/data_set/mvp_data/CMA-RA
A30: =INDEX(数据源对应的文献以及数据使用方法和条目需求!A:B,MATCH(B30,数据源对应的文献以及数据使用方法和条目需求!B:B,0),1) -> ERA5相关性数据 | B30: AIA-1088 | C30: 使用✅ | D30: 全球高空探空数据(IGRA，NOAA) | E30: 气象与环境 | F30: 气象与环境 | G30: 时：12h；空：站点级，多高度层 | H30: 🟡 推荐 | I30: TXT/NetCDF | J30: 开源✅ 下载✅ 有数据✅ | K30: NOAA IGRA：https://www.ncei.noaa.gov/products/weather-balloon/integrated-global-radiosonde-archive | Q30: ⭐⭐ 中等 | S30: 增加输入通道，特征融合 | T30: 延迟数小时 | U30: 1905年至今 | V30: 全球
A31: =INDEX(数据源对应的文献以及数据使用方法和条目需求!A:B,MATCH(B31,数据源对应的文献以及数据使用方法和条目需求!B:B,0),1) -> ERA5相关性数据 | B31: AIA-1089 | C31: 使用✅ | D31: 中国高空探空数据(CMA) | E31: 气象与环境 | F31: 气象与环境(高空风速风向-多高度层、大气稳定度) | G31: 时：12h；空：站点级，多高度层 | H31: 🟡 推荐 | I31: TXT/NetCDF | J31: 开源✅ 下载✅(需注册) 有数据✅ | K31: 中国气象数据网：https://data.cma.cn/ | Q31: ⭐⭐ 中等 | S31: 免费(需注册) | T31: 实时/延迟数小时 | U31: 近10-20年 | V31: 中国
A32: =INDEX(数据源对应的文献以及数据使用方法和条目需求!A:B,MATCH(B32,数据源对应的文献以及数据使用方法和条目需求!B:B,0),1) -> ERA5相关性数据 | B32: AIA-1072 | C32: 使用✅ | D32: NOAA NDBC海洋浮标网数据 | E32: 气象与环境 | F32: 气象与环境(高空风速风向-海上补充) | G32: 时：1h；空：浮标站点 | H32: 🟢 可选 | I32: CSV/TXT | J32: 开源✅ 下载✅ 有数据✅ | K32: NOAA NDBC：https://www.ndbc.noaa.gov/ | Q32: ⭐⭐ 中等 | S32: 免费 | T32: 实时/延迟数小时 | U32: 1970年至今 | V32: 美国近海及部分全球海域
A33: =INDEX(数据源对应的文献以及数据使用方法和条目需求!A:B,MATCH(B33,数据源对应的文献以及数据使用方法和条目需求!B:B,0),1) -> ERA5相关性数据 | B33: AIA-1073 | C33: 使用✅ | D33: ICOADS全球海洋综合数据集(全球船舶+浮标综合观测) | E33: 气象与环境 | F33: 气象与环境(高空风速风向-海上补充) | G33: 时：3h/6h；空：站点级 | H33: 🟢 可选 | I33: NetCDF/CSV | J33: 开源✅ 下载✅ 有数据✅ | K33: ICOADS：https://www.ncei.noaa.gov/products/international-comprehensive-ocean-atmosphere-data-set | Q33: ⭐⭐ 中等 | S33: 免费 | T33: 延迟数天 | U33: 1662年至今 | V33: 全球海洋
A34: =INDEX(数据源对应的文献以及数据使用方法和条目需求!A:B,MATCH(B34,数据源对应的文献以及数据使用方法和条目需求!B:B,0),1) -> 海洋气象数据 | B34: AIA-1074 | C34: 使用✅ | D34: ORAS5海洋再分析数据 | E34: 气象与环境 | F34: 气象与环境(高空风速风向-海上补充、海洋背景场) | G34: 时：1天；空：0.25° | H34: 🟢 可选 | I34: NetCDF | J34: 开源✅ 下载✅(需注册) 有数据✅ | K34: ECMWF ORAS5：https://www.ecmwf.int/en/forecasts/datasets/reanalysis-datasets/oras5 | Q34: ⭐⭐ 中等 | S34: 免费(需注册) | T34: 延迟数天 | U34: 1979年至今 | V34: 全球海洋
A35: =INDEX(数据源对应的文献以及数据使用方法和条目需求!A:B,MATCH(B35,数据源对应的文献以及数据使用方法和条目需求!B:B,0),1) -> ERA5相关性数据 | B35: AIA-1075 | C35: 使用✅ | D35: CFSR/CFSv2海洋再分析数据(NCEP海洋+大气再分析) | E35: 气象与环境 | F35: 气象与环境(高空风速风向-多源验证、整体气象背景场) | G35: 时：6h；空：0.5° | H35: 🟡 推荐 | I35: GRIB/NetCDF | J35: 开源✅ 下载✅ 有数据✅ | K35: NCEP CFSR/CFSv2：https://www.ncei.noaa.gov/products/weather-climate-models/climate-forecast-system | Q35: ⭐⭐ 中等 | S35: 免费 | T35: 延迟数天 | U35: CFSR: 1979-2010年；CFSv2: 2011年至今 | V35: 全球
A36: =INDEX(数据源对应的文献以及数据使用方法和条目需求!A:B,MATCH(B36,数据源对应的文献以及数据使用方法和条目需求!B:B,0),1) -> ERA5相关性数据 | B36: AIA-1066 | C36: 使用✅ | D36: NEXRAD天气雷达数据 | E36: 气象与环境 | F36: 气象与环境(近地面微气象-强对流相关) | G36: 时：~5-6min 体扫；空：~1 km，多高度层 | H36: 🟢 可选 | I36: 雷达 Level-II/Level-III | J36: 开源✅ 下载✅ 有数据✅ | K36: NOAA NEXRAD：https://www.ncei.noaa.gov/products/radar/next-generation-weather-radar | Q36: ⭐⭐ 中等 | S36: 免费 | T36: 实时/延迟数分钟 | U36: 1991年至今 | V36: 美国本土及部分海外
A37: =INDEX(数据源对应的文献以及数据使用方法和条目需求!A:B,MATCH(B37,数据源对应的文献以及数据使用方法和条目需求!B:B,0),1) -> ERA5相关性数据 | B37: AIA-1067 | C37: 使用✅ | D37: TDWR终端多普勒天气雷达数据(机场) | E37: 气象与环境 | F37: 气象与环境(近地面微气象-强对流相关) | G37: 时：~1min 体扫；空：~0.5 km，多高度层 | H37: 🟢 可选 | I37: 雷达 Level-II | J37: 开源✅ 下载✅ 有数据✅ | K37: NOAA TDWR：https://www.ncei.noaa.gov/products/radar/terminal-doppler-weather-radar | Q37: ⭐⭐ 中等 | S37: 免费 | T37: 实时/延迟数分钟 | U37: 1994年至今 | V37: 美国主要机场周边
A38: =INDEX(数据源对应的文献以及数据使用方法和条目需求!A:B,MATCH(B38,数据源对应的文献以及数据使用方法和条目需求!B:B,0),1) -> ERA5相关性数据 | B38: AIA-1068 | C38: 使用✅ | D38: GridRad网格化雷达数据 | E38: 气象与环境 | F38: 气象与环境(近地面微气象-强对流相关) | G38: 时：5min；空：0.02°×0.02° (~2km)，多高度层 | H38: 🟢 可选 | I38: NetCDF | J38: 开源✅ 下载✅ 有数据✅ | K38: GridRad：https://gridrad.org/ | Q38: ⭐⭐ 中等 | S38: 免费 | T38: 延迟数小时 | U38: 1995年至今 | V38: 美国本土
A39: =INDEX(数据源对应的文献以及数据使用方法和条目需求!A:B,MATCH(B39,数据源对应的文献以及数据使用方法和条目需求!B:B,0),1) -> ERA5相关性数据 | B39: AIA-1069 | C39: 使用✅ | D39: 中国气象雷达拼图数据 | E39: 气象与环境 | F39: 气象与环境(近地面微气象-强对流相关) | G39: 时：6-10min；空：1-2 km，多高度层 | H39: 🟢 可选 | I39: NetCDF/BUFR | J39: 开源⚠️(需申请) 下载⚠️ 有数据⚠️(视区域) | K39: 中国气象数据网：https://data.cma.cn/（需专项申请） | Q39: ⭐⭐⭐ 困难 | S39: 需协商(需向气象部门申请) | T39: 实时/延迟数分钟 | U39: 近5-10年(视雷达站) | V39: 中国区域
A40: =INDEX(数据源对应的文献以及数据使用方法和条目需求!A:B,MATCH(B40,数据源对应的文献以及数据使用方法和条目需求!B:B,0),1) -> 天气雷达数据 | B40: AIA-1070 | C40: 使用✅ | D40: NASA机载雷达数据 | E40: 气象与环境 | F40: 气象与环境(近地面微气象-强对流相关) | G40: 时：秒级-分钟级；空：~100m-1 km，多高度层 | H40: 🟢 可选 | I40: NetCDF/HDF5 | J40: 开源✅ 下载✅ 有数据✅(特定研究项目) | K40: NASA Airborne Radar：https://www-air.larc.nasa.gov/ | Q40: ⭐⭐⭐ 困难 | S40: 免费(需申请) | T40: 延迟数天-数周 | U40: 特定研究项目期间 | V40: 特定研究区域
...

Sheet 数据源对应的文献以及数据使用方法和条目需求
A1: 数据类型分类 | B1: 编号 | C1: 数据名称 | D1: 分辨率（时/空） | E1: 数据使用 | F1: 对应论文与数据量需求
A2: ERA5相关性数据 | B2: AIA-1064 | C2: 气象站实测ISD(风速/风向/温度/气压/湿度) | D2: 时：1h/3h；空：站点级 | E2: 微调: 作为训练标签，优化模型在站点处的预测。 | F2: [1] (801769条, +DS-013 801769条, +DS-001 1份静态数据, +DS-002 1份静态数据, +DS-001, GPS 1份静态数据, +工程计算 801769条) [3] (10955条） [5] (8764条) [7] (1038条) [8] (8760条) [10] (52560条） [11](210432条, +DS-016 1315200条, +GPS坐标 1份静态数据) [15] (1440条, +DS-013 1440条） [16] (34560条) [17] (210240条) [18] (744条) [19] (1492条) [20] (8760条) [21] (1201条) [22] (12120条) [23] (7776条) [24] (6539条) [25] (2908条) [26] (144条, +DS-005 36条, +DS-019 896条, +DS-014b 1份静态数据) [27] (5000条) [28] (708条, +DS-006 744条, +DS-013 744条, +DS-017 721条, +DS-008 3份静态剖面数据) [29] (1458条) [30] (8372条) {34} (108条, +AIA-1057 4条, +KG-12 1份静态数据, +KG-15 1份静态数据, +NEW-001 1份静态数据, +NEW-003 1份静态数据, +NEW-004 12条)) {39} (676条) {42} (60192条) {43} (3137条) {45} (2928条, +KG-10 1份静态数据, +KG-11 1份静态数据 {50} (52560条, +AIA-1098 365条, +AIA-1094 52560条, +KG-10 1份静态数据) {51} (2592条) {52} (8759条) {53} (70080条, +KG-24 1份静态数据, +KG-25 70080条) {56} (6696条, +KG-25 6696条) {57} (60条, +KG-17 60条) {58} (26280条) {59} (365条) {60} (576条, +AIA-1095 48条, +NEW-010 144条, +KG-16 576条) {61} (17520条) {63} (4464条) {64} (720条) {67} (8760条) {70} (2400~2800条) {72} (11802条) {77} (11946240条, +KG-12 1份静态数据, +AIA-1056 1份静态数据, +AIA-1094 17246040条) {78} (11640条) {83} (26280条, +AIA-1094 26280条) {86} (1208880条, +AIA-1083 297840条) {93} (87600条, +AIA-1064 105120条) {95} (2390条, +AIA-1064 2390条) {96} (1000条, +AIA-1064 1000条) {98} (856080条, +AIA-1064 1048800条) {99} (33216条, +AIA-1064 33216条) {102} (2600条, +AIA-1064 2600条) {117} (35040条, +AIA-1057 35040条, +AIA-1097 8760条) {123} (262800条, +AIA-1056 262800条, +KG-25 262800条) {127} (280320条, +AIA-1057 560640条)
E3: 后处理: 用模型预测与实测值的差作为目标，训练校正器。 | F3: [15] (1440条, +DS-013 1440条） {38} (103512条, +NEW-001 103512条) {92} (13870条, +AIA-1095 13870条)
E4: 增加输入通道 | F4: {93} (105120条, +AIA-1064 87600条) {95} (2390条, +AIA-1064 2390条) {96} (1000条, +AIA-1064 1000条) {98} (1048800条, +AIA-1064 856080条) {99} (33216条, +AIA-1064 33216条) {102} (2600条, +AIA-1064 2600条)
E5: 预测精度对比基线 | F5: {116} (8760条, +AIA-1094 78840条, +AIA-1097 8760条, +KG-10 1份静态数据) {124} (3600条, +AIA-1094 720条, +AIA-1056 60条, +AIA-1057 60条, +KG-10 1份静态数据, +KG-12 1份静态数据) {126} (27864条, +AIA-1072 18576条, +AIA-1094 46440条, +AIA-1056 46440条, +KG-10 1份静态数据, +KG-11 1份静态数据)
E6: 计算大气稳定度的底层数据 | F6: {121} (17520条, +KG-9 26280条, +AIA-1056 26280条, +AIA-1057 26280条, +AIA-1094 26280条)
A7: 官方业务全球预报数据 | B7: AIA-1097 | C7: <0.1°气象同化数据(6通道) | D7: 时：1-3h；空：0.1°(~10 km) | E7: 增加输入通道: 插值到0.25°后与ERA5通道拼接。 | F7: {97} (702条, +AIA-1056 702条)
E8: 特征融合: 设计独立编码器，提取高分辨率特征并与主干融合。
E9: 条件注入 | F9: {116} (8760条, +AIA-1094 78840条, +AIA-1064 8760条, +KG-10 1份静态数据) {120} (288条, +AIA-1056 144条, +AIA-1088 12条)
E10: 微调 | F10: {128} (11680条, +AIA-1056 57000条, +AIA-1057 57000条, +KG-25 68680条)
A11: WRF数据 | B11: AIA-1094 | C11: 区域WRF/COSMO等模式输出 | D11: 时：1-3h；空：1-5 km | E11: 增加输入通道: 将WRF预测作为额外通道。 | F11: [1] (801769条, +DS-009, DS-016 801769条, +DS-001 1份静态数据, +DS-002 1份静态数据, +DS-001, GPS 1份静态数据, +工程计算 801769条) [14] (40704条, +DS-018 40704条) [15] (1440条, +DS-009 1440条) [28] (744条, +DS-006 744条, +DS-017 721条, +DS-015 708条, +DS-008 3份静态剖面数据) [31] (105120条, +KG-16 105120条, +KG-17 105120条) {83} (26280条, +AIA-1064 26280条)
E12: 特征融合: WRF特征作为独立分支。
E13: 条件注入: 若WRF提供模式不确定性，可作为条件注入。 | F13: [26](36条, +DS-019 896条, +DS-009 144条, +DS-014b 1份静态数据)
E14: 提取高分辨率预报风速结合功率曲线，用于评估单一确定性模型的坡道事件预测能力 | F14: {41} (6条, +KG-17 105120条, +NEW-001 72条, +NEW-002 17520条)
E15: 后处理: 校正模型输出。 | F15: {75} (35040条, +AIA-1095 35040条, +KG-16 35040条, +KG-10 1份静态数据, +KG-11 1份静态数据, +KG-15 1份静态数据)
E16: 预测精度对比基线 | F16: {115} (7300条, +KG-9 327767条, +KG-6 52560条, +AIA-1056 52560条) {121} (26280条, +KG-9 26280条, +AIA-1056 26280条, +AIA-1057 26280条, +AIA-1064 17520条)
E17: 核心预测变量 | F17: {116} (78840条, +AIA-1097 8760条, +AIA-1064 8760条, +KG-10 1份静态数据) {118} (175200条, +AIA-1056 175200条, +AIA-1057 175200条, +AIA-1083 8760条, +KG-25 175200条) {124} (720条, +AIA-1064 3600条, +AIA-1056 60条, +AIA-1057 60条, +KG-10 1份静态数据, +KG-12 1份静态数据) {126} (46440条, +AIA-1072 18576条, +AIA-1064 27864条, +AIA-1056 46440条, +KG-10 1份静态数据, +KG-11 1份静态数据)
A18: ERA5相关性数据 | B18: KG-6 | C18: 卫星散射计海面风场 | D18: 时：卫星过境；空：12.5-25 km / 500m-1km | E18: 增加输入通道: 插值后作为海洋表面风输入。
E19: 特征融合: 提取海面风特征，与陆地风特征融合。 [作为空间风场分布的验证标签，用于定性评估各参数化方案模拟的尾流影响范围] | F19: [26](1份静态数据, +DS-005 36条, +DS-019 896条, +DS-009 144条)
E20: 作为输入变量 | F20: {115} (52560条, +KG-9 327767条, +AIA-1056 52560条, +AIA-1094 7300条)
A21: 遥感观测数据 | B21: KG-7 | C21: 卫星云图/水汽图 | D21: 时：10-15min；空：2-8 km | E21: 设计CNN分支处理图像，提取云量、水汽等特征，与主干融合。
A22: 遥感观测数据 | B22: KG-8 | C22: 气象雷达反射率/径向速度 | D22: 时：~6min 体扫；空：~1 km，多高度层 | E22: 设计CNN/RNN分支处理雷达数据立方体，提取强对流特征。
A23: 遥感观测数据 | B23: KG-9 | C23: 激光雷达/声雷达测风剖面 | D23: 时：1s-10min；空：垂直10-300m分层 | E23: 将垂直风廓线作为3D特征输入，或提取关键层次特征与主干融合。 | F23: [28] (721条, +DS-006 744条, +DS-013 744条, +DS-015 708条, +DS-008 3份静态剖面数据)
E24: [模型训练与测试真值] | F24: {115} (327767条, +KG-6 52560条, +AIA-1056 52560条, +AIA-1094 7300条) {119} (8496条, +AIA-1056 1416条, +AIA-1057 1416条, +AIA-1086 59条, +AIA-1072 1416条, +AIA-1070 23条)
E25: 模型评估实测真值 | F25: {121} (26280条, +AIA-1056 26280条, +AIA-1057 26280条, +AIA-1094 26280条, +AIA-1064 17520条) {125} (105120条, +AIA-1072 105120条, +AIA-1094 105120条, +AIA-1056 8760条, +AIA-1057 8760条, +KG-25 105120条, +KG-10 1份静态数据, +KG-12 1份静态数据)
A26: 地理与地表信息数据 | B26: KG-10 | C26: 数字高程模型(DEM) | D26: 时：静态；空：30/90 m | E26: 作为静态通道直接输入模型。 | F26: [1] (1份静态数据, +DS-009, DS-016 801769条, +DS-013 801769条, +DS-002 1份静态数据, +DS-001, GPS 1份静态数据, +工程计算 801769条) {45} (1份静态数据, +KG-11 1份静态数据, +AIA-1064 2928条 {48} (1份静态数据, +AIA-1098 2924条, +AIA-1094 2385984条, +KG-16 2385984条)
E27: 作为边界特征输入 | F27: {46} (1份静态数据, +AIA-1098 365条, +AIA-1094 35040条, +KG-16 35040条, +KG-17 35040条) {50} (1份静态数据, +AIA-1098 365条, +AIA-1094 52560条, +NEW-001 52560条) {75} (1份静态数据, +AIA-1095 35040条, +AIA-1094 35040条, +KG-16 35040条, +KG-11 1份静态数据, +KG-15 1份静态数据)
E28: 用于构建CFD流体动力学仿真的38km×25km三维复杂地形计算域模型 | F28: {71} (1份静态数据, +KG-12 1份静态数据, +011 3000条)
E29: 特征融合 | F29: {116} (1份静态数据, +AIA-1094 78840条, +AIA-1097 8760条, +AIA-1064 8760条) {124} (1份静态数据, +AIA-1094 720条, +AIA-1064 3600条, +AIA-1056 60条, +AIA-1057 60条, +KG-12 1份静态数据) {125} (1份静态数据, +KG-9 105120条, +AIA-1072 105120条, +AIA-1094 105120条, +AIA-1056 8760条, +AIA-1057 8760条, +KG-25 105120条, +KG-12 1份静态数据) {126} (1份静态数据, +AIA-1072 18576条, +AIA-1064 27864条, +AIA-1094 46440条, +AIA-1056 46440条, +KG-11 1份静态数据)
A30: 地理与地表信息数据 | B30: KG-11 | C30: 地表粗糙度长度 | D30: 时：年度；空：10-30 m | E30: 作为静态通道直接输入模型。 | F30: {45} (1份静态数据, +KG-10 1份静态数据, +AIA-1064 2928条, {75} (1份静态数据, +AIA-1095 35040条, +AIA-1094 35040条, +KG-16 35040条, +KG-10 1份静态数据, +KG-15 1份静态数据)
E31: 特征融合 | F31: {126} (1份静态数据, +AIA-1072 18576条, +AIA-1064 27864条, +AIA-1094 46440条, +AIA-1056 46440条, +KG-10 1份静态数据)
A32: 地理与地表信息数据 | B32: KG-12 | C32: 土地利用/土地覆盖(LULC) | D32: 时：年度；空：10-30 m | E32: 增加输入通道: One-hot编码或类别索引作为输入。 | F32: [1] (1份静态数据, +DS-009, DS-016 801769条, +DS-013 801769条, +DS-001 1份静态数据, +DS-001, GPS 1份静态数据, +工程计算 801769条)
E33: 条件注入: 若LULC用于定义区域类型，可作为条件。
E34: 作为WRF中尺度模型的地表静态物理特征输入 | F34: {34} (1份静态数据, +AIA-1057 4条, +KG-15 1份静态数据, +NEW-001 1份静态数据, +NEW-002 108条, +NEW-003 1份静态数据, +NEW-004 12条) {71} (1份静态数据, +KG-10 1份静态数据, +011 3000条) {77} (1份静态数据, +AIA-1056 1份静态数据, +AIA-1094 17246040条, +AIA-1064 11946240条)
E35: 特征融合 | F35: {124} (1份静态数据, +AIA-1094 720条, +AIA-1064 3600条, +AIA-1056 60条, +AIA-1057 60条, +KG-10 1份静态数据) {125} (1份静态数据, +KG-9 105120条, +AIA-1072 105120条, +AIA-1094 105120条, +AIA-1056 8760条, +AIA-1057 8760条, +KG-25 105120条, +KG-10 1份静态数据)
A36: 地理与地表信息数据 | B36: KG-13 | C36: 植被指数(NDVI) | D36: 时：16天/或月度；空：250m/10m | E36: 作为动态通道（随时间变化）输入模型。
A37: 地理与地表信息数据 | B37: KG-14 | C37: 建筑物高度与密度数据 | D37: 时：静态；空：10-100 m | E37: 作为高分辨率静态通道输入模型。
A38: 风电场特定数据 | B38: KG-15 | C38: 风机位置与布局图 | D38: 时：静态；空：单风机级 | E38: 增加输入通道: 作为二值掩码或距离图输入。 | F38: [26](896条, +DS-005 36条, +DS-009 144条, +DS-014b 1份静态数据) {61} (17520条)
E39: 图神经网络: 将风机作为图节点。
E40: 用于提供WRF风电场参数化方案(Fitch和EWP)的机位与气动特性设置 | F40: {34} (1份静态数据, +AIA-1057 4条, +KG-12 1份静态数据, +NEW-001 1份静态数据, +NEW-002 108条, +NEW-003 1份静态数据, +NEW-004 12条)
...

Sheet 气象站(舟山定海)数据字段
A1: 字段名 | B1: 物理量 | C1: 官方定义 | D1: 通俗解释 | E1: 示例值 | F1: 数据类型 | G1: 单位
